Workbook

Sheet Configuração
B3: Configuração de custos
B5: Atributos sobre a forma de trabalho do cliente | C5: Config | E5: % Base | F5: $ Incremento
B6: Fornece máquina | D6: VERDADEIRO | E6: 3 | F6: =IF(D6=FALSE, E6%,0%) -> 0
B7: Fornece monitor adicional | D7: VERDADEIRO | E7: 0 | F7: =IF(D7=FALSE, E7%,0%) -> 0
B8: Fornece licenças necessárias | D8: VERDADEIRO | E8: 3 | F8: =IF(D8=FALSE, E8%,0%) -> 0
B9: Horas abertas | D9: TRUE | E9: 0.5 | F9: =IF(D9=FALSE, E9%,0%) -> 0
B10: Modo de trabalho | C10: Full Home | D10: =C10 -> Full Home | E10: 1 | F10: =IF(D10="Presencial",E10%, IF(D10="Híbrido",(E10/2)%, 0%)) -> 0
B11: Aceita colaboradores de outros estados | D11: TRUE | E11: 1 | F11: =IF(D11=FALSE, E11%,0%) -> 0
B12: Risco de atraso | C12: Baixo | D12: =C12 -> Baixo | E12: 3 | F12: =IF(D12="Alto",E12%, IF(D12="Médio",(E12/2)%, 0%)) -> 0
F13: =SUM(F6:F12) -> 0

Sheet Célula Base
E2: RESUMO | F2: Base horas mês | G2: 168 | H2: $ salários + encargos | I2: =SUM(I9:I33) -> #N/A | J2: FGTS | K2: 0.08 | L2: Nº colab bilable | M2: =COUNTIF(E9:E494, "Sim") -> 5 | N2: Valor convênio | O2: 400
F3: % Comissão vend. | G3: 0 | H3: $ faturamento | I3: =SUM(Q9:Q33) -> #N/A | J3: FGTS Multa | K3: 0.4 | L3: Nº colab no bilable | M3: =COUNTIF(E9:E494, "Não") -> 1 | N3: Valor comissão | O3: =SUM(P9:P33) -> #N/A
F4: % Imposto NF | G4: 0.1953 | H4: $ Custos | I4: =SUM(J9:J494)+SUM(M9:M494)+O3 -> #N/A | J4: INSS | K4: 0.09 | L4: % Rateio no Bilable | M4: =M6/M5 -> #N/A
G5: 1 | H5: $ lucratividade | I5: =I3-I4 -> #N/A | J5: Ticket Rest. Dia | K5: 30 | L5: Total Billable | M5: =SUMIF(E9:E33,"Sim",O9:O33) -> #N/A
F6: Taxa de risco | G6: =Configuração!F13 -> 0 | H6: % lucro real | I6: =I5/I3 -> #N/A | J6: Tarifa média hr. | K6: =SUM(Q9:Q33)/SUM(D9:D33) -> #N/A | L6: Total No Bilable | M6: =SUMIF(E9:E33,"Não",O9:O33) -> #N/A
B7: CONFIGURAÇÃO EQUIPE | C7: CONFIG RECURSO | F7: C U S T O S C O M C O L A B O R A D O R E S | K7: T A R I F A / F A T U R A M E N T O | S7: C U S T O S C L T | AC7: IMPOSTOS | AD7: LUCRATIVIDADE
B8: Necessidade cliente | C8: Reg | D8: H.trab | E8: Billable | F8: $ Negociado/salário | G8: $ salário cheio | H8: $ Salário real | I8: $ Custo Colab | J8: $ Custo colab + Imp | K8: $ Tarifa negociada | L8: Markup | M8: $ Risco | N8: $ Tar. cheia | O8: $ Tar. calculada | P8: $ Comissão | Q8: $ Tarifa bilable | R8: Valor hora | S8: FGTS | T8: FGTS multa | U8: Férias | V8: 1/3 férias | W8: 13º salário | X8: Aviso Remuner | Y8: Vl. Restaurante | Z8: INSS | AA8: Convênio | AB8: $ Total Encargos | AC8: Imposto Nota | AD8: $ lucro | AE8: % Lucro
B9: Gerente T.I. Gestão | C9: PJ | D9: 20 | E9: Não | F9: 0 | G9: =IF(F9>0,F9, IF(B9<>"", IF(C9="CLT",VLOOKUP(B9,'Lista Profissionais'!$C$11:$H$348,3,0), VLOOKUP(B9,'Lista Profissionais'!$C$11:$H$348,4,0)), 0)) -> #N/A | H9: =(G9/$G$2)*D9 -> #N/A | I9: =H9+AB9 -> #N/A | J9: =I9+AC9 -> #N/A | K9: 0 | L9: 0 | M9: =I9*$G$6 -> #N/A | N9: =IF(K9>0,K9, IF(L9>0,(G9*(1+L9)+M9), (G9*(1+$G$5)+M9))) -> #N/A | O9: =(N9/$G$2)*D9 -> #N/A | P9: =IF(E9="Sim", O9*$G$3,0) -> 0 | Q9: =IF(E9="Não",0, O9+(O9*$M$4)+P9 ) -> 0 | R9: =Q9/$G$2 -> 0 | S9: =IF(C9="CLT", H9*$K$2, 0) -> 0 | T9: =IF(C9="CLT", S9*$K$3, 0) -> 0 | U9: =IF(C9="CLT", H9/12, 0) -> 0 | V9: =IF(C9="CLT", U9/3, 0) -> 0 | W9: =IF(C9="CLT", H9/12, 0) -> 0 | X9: =IF(C9="CLT", H9/12, 0) -> 0 | Y9: =IF(B9<>"", IF(C9="CLT", 22*$K$5,0),0) -> 0 | Z9: =IF(C9="CLT", H9*$K$4, 0) -> 0 | AA9: =IF(B9<>"", IF(C9="CLT", $O$2, 0),0) -> 0 | AB9: =SUM(S9:AA9) -> 0 | AC9: =IF(E9="Sim", Q9*$G$4, 0) -> 0 | AD9: =Q9-AC9-I9-M9-P9 -> #N/A | AE9: =(IF(AD9>0,AD9/Q9,0)) -> #N/A
B10: Coordenador de Qualidade de Software Gestão | C10: PJ | D10: 168 | E10: Sim | F10: 0 | G10: =IF(F10>0,F10, IF(B10<>"", IF(C10="CLT",VLOOKUP(B10,'Lista Profissionais'!$C$11:$H$348,3,0), VLOOKUP(B10,'Lista Profissionais'!$C$11:$H$348,4,0)), 0)) -> #N/A | H10: =(G10/$G$2)*D10 -> #N/A | I10: =H10+AB10 -> #N/A | J10: =I10+AC10 -> #N/A | K10: 0 | L10: 0 | M10: =I10*$G$6 -> #N/A | N10: =IF(K10>0,K10, IF(L10>0,(G10*(1+L10)+M10), (G10*(1+$G$5)+M10))) -> #N/A | O10: =(N10/$G$2)*D10 -> #N/A | P10: =IF(E10="Sim", O10*$G$3,0) -> #N/A | Q10: =IF(E10="Não",0, O10+(O10*$M$4)+P10 ) -> #N/A | R10: =Q10/$G$2 -> #N/A | S10: =IF(C10="CLT", H10*$K$2, 0) -> 0 | T10: =IF(C10="CLT", S10*$K$3, 0) -> 0 | U10: =IF(C10="CLT", H10/12, 0) -> 0 | V10: =IF(C10="CLT", U10/3, 0) -> 0 | W10: =IF(C10="CLT", H10/12, 0) -> 0 | X10: =IF(C10="CLT", H10/12, 0) -> 0 | Y10: =IF(B10<>"", IF(C10="CLT", 22*$K$5,0),0) -> 0 | Z10: =IF(C10="CLT", H10*$K$4, 0) -> 0 | AA10: =IF(B10<>"", IF(C10="CLT", $O$2, 0),0) -> 0 | AB10: =SUM(S10:AA10) -> 0 | AC10: =IF(E10="Sim", Q10*$G$4, 0) -> #N/A | AD10: =Q10-AC10-I10-M10-P10 -> #N/A | AE10: =(IF(AD10>0,AD10/Q10,"")) -> #N/A
B11: Analista Q.A. Sênior | C11: PJ | D11: 168 | E11: Sim | F11: 0 | G11: =IF(F11>0,F11, IF(B11<>"", IF(C11="CLT",VLOOKUP(B11,'Lista Profissionais'!$C$11:$H$348,3,0), VLOOKUP(B11,'Lista Profissionais'!$C$11:$H$348,4,0)), 0)) -> #N/A | H11: =(G11/$G$2)*D11 -> #N/A | I11: =H11+AB11 -> #N/A | J11: =I11+AC11 -> #N/A | K11: 0 | L11: 0 | M11: =I11*$G$6 -> #N/A | N11: =IF(K11>0,K11, IF(L11>0,(G11*(1+L11)+M11), (G11*(1+$G$5)+M11))) -> #N/A | O11: =(N11/$G$2)*D11 -> #N/A | P11: =IF(E11="Sim", O11*$G$3,0) -> #N/A | Q11: =IF(E11="Não",0, O11+(O11*$M$4)+P11 ) -> #N/A | R11: =Q11/$G$2 -> #N/A | S11: =IF(C11="CLT", H11*$K$2, 0) -> 0 | T11: =IF(C11="CLT", S11*$K$3, 0) -> 0 | U11: =IF(C11="CLT", H11/12, 0) -> 0 | V11: =IF(C11="CLT", U11/3, 0) -> 0 | W11: =IF(C11="CLT", H11/12, 0) -> 0 | X11: =IF(C11="CLT", H11/12, 0) -> 0 | Y11: =IF(B11<>"", IF(C11="CLT", 22*$K$5,0),0) -> 0 | Z11: =IF(C11="CLT", H11*$K$4, 0) -> 0 | AA11: =IF(B11<>"", IF(C11="CLT", $O$2, 0),0) -> 0 | AB11: =SUM(S11:AA11) -> 0 | AC11: =IF(E11="Sim", Q11*$G$4, 0) -> #N/A | AD11: =Q11-AC11-I11-M11-P11 -> #N/A | AE11: =(IF(AD11>0,AD11/Q11,"")) -> #N/A
B12: Analista Q.A. Pleno | C12: PJ | D12: 168 | E12: Sim | F12: 0 | G12: =IF(F12>0,F12, IF(B12<>"", IF(C12="CLT",VLOOKUP(B12,'Lista Profissionais'!$C$11:$H$348,3,0), VLOOKUP(B12,'Lista Profissionais'!$C$11:$H$348,4,0)), 0)) -> #N/A | H12: =(G12/$G$2)*D12 -> #N/A | I12: =H12+AB12 -> #N/A | J12: =I12+AC12 -> #N/A | K12: 0 | L12: 0 | M12: =I12*$G$6 -> #N/A | N12: =IF(K12>0,K12, IF(L12>0,(G12*(1+L12)+M12), (G12*(1+$G$5)+M12))) -> #N/A | O12: =(N12/$G$2)*D12 -> #N/A | P12: =IF(E12="Sim", O12*$G$3,0) -> #N/A | Q12: =IF(E12="Não",0, O12+(O12*$M$4)+P12 ) -> #N/A | R12: =Q12/$G$2 -> #N/A | S12: =IF(C12="CLT", H12*$K$2, 0) -> 0 | T12: =IF(C12="CLT", S12*$K$3, 0) -> 0 | U12: =IF(C12="CLT", H12/12, 0) -> 0 | V12: =IF(C12="CLT", U12/3, 0) -> 0 | W12: =IF(C12="CLT", H12/12, 0) -> 0 | X12: =IF(C12="CLT", H12/12, 0) -> 0 | Y12: =IF(B12<>"", IF(C12="CLT", 22*$K$5,0),0) -> 0 | Z12: =IF(C12="CLT", H12*$K$4, 0) -> 0 | AA12: =IF(B12<>"", IF(C12="CLT", $O$2, 0),0) -> 0 | AB12: =SUM(S12:AA12) -> 0 | AC12: =IF(E12="Sim", Q12*$G$4, 0) -> #N/A | AD12: =Q12-AC12-I12-M12-P12 -> #N/A | AE12: =(IF(AD12>0,AD12/Q12,"")) -> #N/A
B13: Analista Q.A. Júnior | C13: PJ | D13: 168 | E13: Sim | F13: 0 | G13: =IF(F13>0,F13, IF(B13<>"", IF(C13="CLT",VLOOKUP(B13,'Lista Profissionais'!$C$11:$H$348,3,0), VLOOKUP(B13,'Lista Profissionais'!$C$11:$H$348,4,0)), 0)) -> #N/A | H13: =(G13/$G$2)*D13 -> #N/A | I13: =H13+AB13 -> #N/A | J13: =I13+AC13 -> #N/A | K13: 0 | L13: 0 | M13: =I13*$G$6 -> #N/A | N13: =IF(K13>0,K13, IF(L13>0,(G13*(1+L13)+M13), (G13*(1+$G$5)+M13))) -> #N/A | O13: =(N13/$G$2)*D13 -> #N/A | P13: =IF(E13="Sim", O13*$G$3,0) -> #N/A | Q13: =IF(E13="Não",0, O13+(O13*$M$4)+P13 ) -> #N/A | R13: =Q13/$G$2 -> #N/A | S13: =IF(C13="CLT", H13*$K$2, 0) -> 0 | T13: =IF(C13="CLT", S13*$K$3, 0) -> 0 | U13: =IF(C13="CLT", H13/12, 0) -> 0 | V13: =IF(C13="CLT", U13/3, 0) -> 0 | W13: =IF(C13="CLT", H13/12, 0) -> 0 | X13: =IF(C13="CLT", H13/12, 0) -> 0 | Y13: =IF(B13<>"", IF(C13="CLT", 22*$K$5,0),0) -> 0 | Z13: =IF(C13="CLT", H13*$K$4, 0) -> 0 | AA13: =IF(B13<>"", IF(C13="CLT", $O$2, 0),0) -> 0 | AB13: =SUM(S13:AA13) -> 0 | AC13: =IF(E13="Sim", Q13*$G$4, 0) -> #N/A | AD13: =Q13-AC13-I13-M13-P13 -> #N/A | AE13: =(IF(AD13>0,AD13/Q13,"")) -> #N/A
B14: Analista Q.A. Júnior | C14: PJ | D14: 168 | E14: Sim | F14: 0 | G14: =IF(F14>0,F14, IF(B14<>"", IF(C14="CLT",VLOOKUP(B14,'Lista Profissionais'!$C$11:$H$348,3,0), VLOOKUP(B14,'Lista Profissionais'!$C$11:$H$348,4,0)), 0)) -> #N/A | H14: =(G14/$G$2)*D14 -> #N/A | I14: =H14+AB14 -> #N/A | J14: =I14+AC14 -> #N/A | K14: 0 | L14: 0 | M14: =I14*$G$6 -> #N/A | N14: =IF(K14>0,K14, IF(L14>0,(G14*(1+L14)+M14), (G14*(1+$G$5)+M14))) -> #N/A | O14: =(N14/$G$2)*D14 -> #N/A | P14: =IF(E14="Sim", O14*$G$3,0) -> #N/A | Q14: =IF(E14="Não",0, O14+(O14*$M$4)+P14 ) -> #N/A | R14: =Q14/$G$2 -> #N/A | S14: =IF(C14="CLT", H14*$K$2, 0) -> 0 | T14: =IF(C14="CLT", S14*$K$3, 0) -> 0 | U14: =IF(C14="CLT", H14/12, 0) -> 0 | V14: =IF(C14="CLT", U14/3, 0) -> 0 | W14: =IF(C14="CLT", H14/12, 0) -> 0 | X14: =IF(C14="CLT", H14/12, 0) -> 0 | Y14: =IF(B14<>"", IF(C14="CLT", 22*$K$5,0),0) -> 0 | Z14: =IF(C14="CLT", H14*$K$4, 0) -> 0 | AA14: =IF(B14<>"", IF(C14="CLT", $O$2, 0),0) -> 0 | AB14: =SUM(S14:AA14) -> 0 | AC14: =IF(E14="Sim", Q14*$G$4, 0) -> #N/A | AD14: =Q14-AC14-I14-M14-P14 -> #N/A | AE14: =(IF(AD14>0,AD14/Q14,"")) -> #N/A
C15: PJ | F15: 0 | G15: =IF(F15>0,F15, IF(B15<>"", IF(C15="CLT",VLOOKUP(B15,'Lista Profissionais'!$C$11:$H$348,3,0), VLOOKUP(B15,'Lista Profissionais'!$C$11:$H$348,4,0)), 0)) -> 0 | H15: =(G15/$G$2)*D15 -> 0 | I15: =H15+AB15 -> 0 | J15: =I15+AC15 -> 0 | K15: 0 | L15: 0 | M15: =I15*$G$6 -> 0 | N15: =IF(K15>0,K15, IF(L15>0,(G15*(1+L15)+M15), (G15*(1+$G$5)+M15))) -> 0 | O15: =(N15/$G$2)*D15 -> 0 | P15: =IF(E15="Sim", O15*$G$3,0) -> 0 | Q15: =IF(E15="Não",0, O15+(O15*$M$4)+P15 ) -> #N/A | R15: =Q15/$G$2 -> #N/A | S15: =IF(C15="CLT", H15*$K$2, 0) -> 0 | T15: =IF(C15="CLT", S15*$K$3, 0) -> 0 | U15: =IF(C15="CLT", H15/12, 0) -> 0 | V15: =IF(C15="CLT", U15/3, 0) -> 0 | W15: =IF(C15="CLT", H15/12, 0) -> 0 | X15: =IF(C15="CLT", H15/12, 0) -> 0 | Y15: =IF(B15<>"", IF(C15="CLT", 22*$K$5,0),0) -> 0 | Z15: =IF(C15="CLT", H15*$K$4, 0) -> 0 | AA15: =IF(B15<>"", IF(C15="CLT", $O$2, 0),0) -> 0 | AB15: =SUM(S15:AA15) -> 0 | AC15: =IF(E15="Sim", Q15*$G$4, 0) -> 0 | AD15: =Q15-AC15-I15-M15-P15 -> #N/A | AE15: =(IF(AD15>0,AD15/Q15,"")) -> #N/A
C16: PJ | F16: 0 | G16: =IF(F16>0,F16, IF(B16<>"", IF(C16="CLT",VLOOKUP(B16,'Lista Profissionais'!$C$11:$H$348,3,0), VLOOKUP(B16,'Lista Profissionais'!$C$11:$H$348,4,0)), 0)) -> 0 | H16: =(G16/$G$2)*D16 -> 0 | I16: =H16+AB16 -> 0 | J16: =I16+AC16 -> 0 | K16: 0 | L16: 0 | M16: =I16*$G$6 -> 0 | N16: =IF(K16>0,K16, IF(L16>0,(G16*(1+L16)+M16), (G16*(1+$G$5)+M16))) -> 0 | O16: =(N16/$G$2)*D16 -> 0 | P16: =IF(E16="Sim", O16*$G$3,0) -> 0 | Q16: =IF(E16="Não",0, O16+(O16*$M$4)+P16 ) -> #N/A | R16: =Q16/$G$2 -> #N/A | S16: =IF(C16="CLT", H16*$K$2, 0) -> 0 | T16: =IF(C16="CLT", S16*$K$3, 0) -> 0 | U16: =IF(C16="CLT", H16/12, 0) -> 0 | V16: =IF(C16="CLT", U16/3, 0) -> 0 | W16: =IF(C16="CLT", H16/12, 0) -> 0 | X16: =IF(C16="CLT", H16/12, 0) -> 0 | Y16: =IF(B16<>"", IF(C16="CLT", 22*$K$5,0),0) -> 0 | Z16: =IF(C16="CLT", H16*$K$4, 0) -> 0 | AA16: =IF(B16<>"", IF(C16="CLT", $O$2, 0),0) -> 0 | AB16: =SUM(S16:AA16) -> 0 | AC16: =IF(E16="Sim", Q16*$G$4, 0) -> 0 | AD16: =Q16-AC16-I16-M16-P16 -> #N/A | AE16: =(IF(AD16>0,AD16/Q16,"")) -> #N/A
C17: PJ | F17: 0 | G17: =IF(F17>0,F17, IF(B17<>"", IF(C17="CLT",VLOOKUP(B17,'Lista Profissionais'!$C$11:$H$348,3,0), VLOOKUP(B17,'Lista Profissionais'!$C$11:$H$348,4,0)), 0)) -> 0 | H17: =(G17/$G$2)*D17 -> 0 | I17: =H17+AB17 -> 0 | J17: =I17+AC17 -> 0 | K17: 0 | L17: 0 | M17: =I17*$G$6 -> 0 | N17: =IF(K17>0,K17, IF(L17>0,(G17*(1+L17)+M17), (G17*(1+$G$5)+M17))) -> 0 | O17: =(N17/$G$2)*D17 -> 0 | P17: =IF(E17="Sim", O17*$G$3,0) -> 0 | Q17: =IF(E17="Não",0, O17+(O17*$M$4)+P17 ) -> #N/A | R17: =Q17/$G$2 -> #N/A | S17: =IF(C17="CLT", H17*$K$2, 0) -> 0 | T17: =IF(C17="CLT", S17*$K$3, 0) -> 0 | U17: =IF(C17="CLT", H17/12, 0) -> 0 | V17: =IF(C17="CLT", U17/3, 0) -> 0 | W17: =IF(C17="CLT", H17/12, 0) -> 0 | X17: =IF(C17="CLT", H17/12, 0) -> 0 | Y17: =IF(B17<>"", IF(C17="CLT", 22*$K$5,0),0) -> 0 | Z17: =IF(C17="CLT", H17*$K$4, 0) -> 0 | AA17: =IF(B17<>"", IF(C17="CLT", $O$2, 0),0) -> 0 | AB17: =SUM(S17:AA17) -> 0 | AC17: =IF(E17="Sim", Q17*$G$4, 0) -> 0 | AD17: =Q17-AC17-I17-M17-P17 -> #N/A | AE17: =(IF(AD17>0,AD17/Q17,"")) -> #N/A
C18: PJ | F18: 0 | G18: =IF(F18>0,F18, IF(B18<>"", IF(C18="CLT",VLOOKUP(B18,'Lista Profissionais'!$C$11:$H$348,3,0), VLOOKUP(B18,'Lista Profissionais'!$C$11:$H$348,4,0)), 0)) -> 0 | H18: =(G18/$G$2)*D18 -> 0 | I18: =H18+AB18 -> 0 | J18: =I18+AC18 -> 0 | K18: 0 | L18: 0 | M18: =I18*$G$6 -> 0 | N18: =IF(K18>0,K18, IF(L18>0,(G18*(1+L18)+M18), (G18*(1+$G$5)+M18))) -> 0 | O18: =(N18/$G$2)*D18 -> 0 | P18: =IF(E18="Sim", O18*$G$3,0) -> 0 | Q18: =IF(E18="Não",0, O18+(O18*$M$4)+P18 ) -> #N/A | R18: =Q18/$G$2 -> #N/A | S18: =IF(C18="CLT", H18*$K$2, 0) -> 0 | T18: =IF(C18="CLT", S18*$K$3, 0) -> 0 | U18: =IF(C18="CLT", H18/12, 0) -> 0 | V18: =IF(C18="CLT", U18/3, 0) -> 0 | W18: =IF(C18="CLT", H18/12, 0) -> 0 | X18: =IF(C18="CLT", H18/12, 0) -> 0 | Y18: =IF(B18<>"", IF(C18="CLT", 22*$K$5,0),0) -> 0 | Z18: =IF(C18="CLT", H18*$K$4, 0) -> 0 | AA18: =IF(B18<>"", IF(C18="CLT", $O$2, 0),0) -> 0 | AB18: =SUM(S18:AA18) -> 0 | AC18: =IF(E18="Sim", Q18*$G$4, 0) -> 0 | AD18: =Q18-AC18-I18-M18-P18 -> #N/A | AE18: =(IF(AD18>0,AD18/Q18,"")) -> #N/A
C19: PJ | F19: 0 | G19: =IF(F19>0,F19, IF(B19<>"", IF(C19="CLT",VLOOKUP(B19,'Lista Profissionais'!$C$11:$H$348,3,0), VLOOKUP(B19,'Lista Profissionais'!$C$11:$H$348,4,0)), 0)) -> 0 | H19: =(G19/$G$2)*D19 -> 0 | I19: =H19+AB19 -> 0 | J19: =I19+AC19 -> 0 | K19: 0 | L19: 0 | M19: =I19*$G$6 -> 0 | N19: =IF(K19>0,K19, IF(L19>0,(G19*(1+L19)+M19), (G19*(1+$G$5)+M19))) -> 0 | O19: =(N19/$G$2)*D19 -> 0 | P19: =IF(E19="Sim", O19*$G$3,0) -> 0 | Q19: =IF(E19="Não",0, O19+(O19*$M$4)+P19 ) -> #N/A | R19: =Q19/$G$2 -> #N/A | S19: =IF(C19="CLT", H19*$K$2, 0) -> 0 | T19: =IF(C19="CLT", S19*$K$3, 0) -> 0 | U19: =IF(C19="CLT", H19/12, 0) -> 0 | V19: =IF(C19="CLT", U19/3, 0) -> 0 | W19: =IF(C19="CLT", H19/12, 0) -> 0 | X19: =IF(C19="CLT", H19/12, 0) -> 0 | Y19: =IF(B19<>"", IF(C19="CLT", 22*$K$5,0),0) -> 0 | Z19: =IF(C19="CLT", H19*$K$4, 0) -> 0 | AA19: =IF(B19<>"", IF(C19="CLT", $O$2, 0),0) -> 0 | AB19: =SUM(S19:AA19) -> 0 | AC19: =IF(E19="Sim", Q19*$G$4, 0) -> 0 | AD19: =Q19-AC19-I19-M19-P19 -> #N/A | AE19: =(IF(AD19>0,AD19/Q19,"")) -> #N/A
C20: PJ | F20: 0 | G20: =IF(F20>0,F20, IF(B20<>"", IF(C20="CLT",VLOOKUP(B20,'Lista Profissionais'!$C$11:$H$348,3,0), VLOOKUP(B20,'Lista Profissionais'!$C$11:$H$348,4,0)), 0)) -> 0 | H20: =(G20/$G$2)*D20 -> 0 | I20: =H20+AB20 -> 0 | J20: =I20+AC20 -> 0 | K20: 0 | L20: 0 | M20: =I20*$G$6 -> 0 | N20: =IF(K20>0,K20, IF(L20>0,(G20*(1+L20)+M20), (G20*(1+$G$5)+M20))) -> 0 | O20: =(N20/$G$2)*D20 -> 0 | P20: =IF(E20="Sim", O20*$G$3,0) -> 0 | Q20: =IF(E20="Não",0, O20+(O20*$M$4)+P20 ) -> #N/A | R20: =Q20/$G$2 -> #N/A | S20: =IF(C20="CLT", H20*$K$2, 0) -> 0 | T20: =IF(C20="CLT", S20*$K$3, 0) -> 0 | U20: =IF(C20="CLT", H20/12, 0) -> 0 | V20: =IF(C20="CLT", U20/3, 0) -> 0 | W20: =IF(C20="CLT", H20/12, 0) -> 0 | X20: =IF(C20="CLT", H20/12, 0) -> 0 | Y20: =IF(B20<>"", IF(C20="CLT", 22*$K$5,0),0) -> 0 | Z20: =IF(C20="CLT", H20*$K$4, 0) -> 0 | AA20: =IF(B20<>"", IF(C20="CLT", $O$2, 0),0) -> 0 | AB20: =SUM(S20:AA20) -> 0 | AC20: =IF(E20="Sim", Q20*$G$4, 0) -> 0 | AD20: =Q20-AC20-I20-M20-P20 -> #N/A | AE20: =(IF(AD20>0,AD20/Q20,"")) -> #N/A
C21: PJ | F21: 0 | G21: =IF(F21>0,F21, IF(B21<>"", IF(C21="CLT",VLOOKUP(B21,'Lista Profissionais'!$C$11:$H$348,3,0), VLOOKUP(B21,'Lista Profissionais'!$C$11:$H$348,4,0)), 0)) -> 0 | H21: =(G21/$G$2)*D21 -> 0 | I21: =H21+AB21 -> 0 | J21: =I21+AC21 -> 0 | K21: 0 | L21: 0 | M21: =I21*$G$6 -> 0 | N21: =IF(K21>0,K21, IF(L21>0,(G21*(1+L21)+M21), (G21*(1+$G$5)+M21))) -> 0 | O21: =(N21/$G$2)*D21 -> 0 | P21: =IF(E21="Sim", O21*$G$3,0) -> 0 | Q21: =IF(E21="Não",0, O21+(O21*$M$4)+P21 ) -> #N/A | R21: =Q21/$G$2 -> #N/A | S21: =IF(C21="CLT", H21*$K$2, 0) -> 0 | T21: =IF(C21="CLT", S21*$K$3, 0) -> 0 | U21: =IF(C21="CLT", H21/12, 0) -> 0 | V21: =IF(C21="CLT", U21/3, 0) -> 0 | W21: =IF(C21="CLT", H21/12, 0) -> 0 | X21: =IF(C21="CLT", H21/12, 0) -> 0 | Y21: =IF(B21<>"", IF(C21="CLT", 22*$K$5,0),0) -> 0 | Z21: =IF(C21="CLT", H21*$K$4, 0) -> 0 | AA21: =IF(B21<>"", IF(C21="CLT", $O$2, 0),0) -> 0 | AB21: =SUM(S21:AA21) -> 0 | AC21: =IF(E21="Sim", Q21*$G$4, 0) -> 0 | AD21: =Q21-AC21-I21-M21-P21 -> #N/A | AE21: =(IF(AD21>0,AD21/Q21,"")) -> #N/A
C22: PJ | F22: 0 | G22: =IF(F22>0,F22, IF(B22<>"", IF(C22="CLT",VLOOKUP(B22,'Lista Profissionais'!$C$11:$H$348,3,0), VLOOKUP(B22,'Lista Profissionais'!$C$11:$H$348,4,0)), 0)) -> 0 | H22: =(G22/$G$2)*D22 -> 0 | I22: =H22+AB22 -> 0 | J22: =I22+AC22 -> 0 | K22: 0 | L22: 0 | M22: =I22*$G$6 -> 0 | N22: =IF(K22>0,K22, IF(L22>0,(G22*(1+L22)+M22), (G22*(1+$G$5)+M22))) -> 0 | O22: =(N22/$G$2)*D22 -> 0 | P22: =IF(E22="Sim", O22*$G$3,0) -> 0 | Q22: =IF(E22="Não",0, O22+(O22*$M$4)+P22 ) -> #N/A | R22: =Q22/$G$2 -> #N/A | S22: =IF(C22="CLT", H22*$K$2, 0) -> 0 | T22: =IF(C22="CLT", S22*$K$3, 0) -> 0 | U22: =IF(C22="CLT", H22/12, 0) -> 0 | V22: =IF(C22="CLT", U22/3, 0) -> 0 | W22: =IF(C22="CLT", H22/12, 0) -> 0 | X22: =IF(C22="CLT", H22/12, 0) -> 0 | Y22: =IF(B22<>"", IF(C22="CLT", 22*$K$5,0),0) -> 0 | Z22: =IF(C22="CLT", H22*$K$4, 0) -> 0 | AA22: =IF(B22<>"", IF(C22="CLT", $O$2, 0),0) -> 0 | AB22: =SUM(S22:AA22) -> 0 | AC22: =IF(E22="Sim", Q22*$G$4, 0) -> 0 | AD22: =Q22-AC22-I22-M22-P22 -> #N/A | AE22: =(IF(AD22>0,AD22/Q22,"")) -> #N/A
C23: PJ | F23: 0 | G23: =IF(F23>0,F23, IF(B23<>"", IF(C23="CLT",VLOOKUP(B23,'Lista Profissionais'!$C$11:$H$348,3,0), VLOOKUP(B23,'Lista Profissionais'!$C$11:$H$348,4,0)), 0)) -> 0 | H23: =(G23/$G$2)*D23 -> 0 | I23: =H23+AB23 -> 0 | J23: =I23+AC23 -> 0 | K23: 0 | L23: 0 | M23: =I23*$G$6 -> 0 | N23: =IF(K23>0,K23, IF(L23>0,(G23*(1+L23)+M23), (G23*(1+$G$5)+M23))) -> 0 | O23: =(N23/$G$2)*D23 -> 0 | P23: =IF(E23="Sim", O23*$G$3,0) -> 0 | Q23: =IF(E23="Não",0, O23+(O23*$M$4)+P23 ) -> #N/A | R23: =Q23/$G$2 -> #N/A | S23: =IF(C23="CLT", H23*$K$2, 0) -> 0 | T23: =IF(C23="CLT", S23*$K$3, 0) -> 0 | U23: =IF(C23="CLT", H23/12, 0) -> 0 | V23: =IF(C23="CLT", U23/3, 0) -> 0 | W23: =IF(C23="CLT", H23/12, 0) -> 0 | X23: =IF(C23="CLT", H23/12, 0) -> 0 | Y23: =IF(B23<>"", IF(C23="CLT", 22*$K$5,0),0) -> 0 | Z23: =IF(C23="CLT", H23*$K$4, 0) -> 0 | AA23: =IF(B23<>"", IF(C23="CLT", $O$2, 0),0) -> 0 | AB23: =SUM(S23:AA23) -> 0 | AC23: =IF(E23="Sim", Q23*$G$4, 0) -> 0 | AD23: =Q23-AC23-I23-M23-P23 -> #N/A | AE23: =(IF(AD23>0,AD23/Q23,"")) -> #N/A
C24: PJ | F24: 0 | G24: =IF(F24>0,F24, IF(B24<>"", IF(C24="CLT",VLOOKUP(B24,'Lista Profissionais'!$C$11:$H$348,3,0), VLOOKUP(B24,'Lista Profissionais'!$C$11:$H$348,4,0)), 0)) -> 0 | H24: =(G24/$G$2)*D24 -> 0 | I24: =H24+AB24 -> 0 | J24: =I24+AC24 -> 0 | K24: 0 | L24: 0 | M24: =I24*$G$6 -> 0 | N24: =IF(K24>0,K24, IF(L24>0,(G24*(1+L24)+M24), (G24*(1+$G$5)+M24))) -> 0 | O24: =(N24/$G$2)*D24 -> 0 | P24: =IF(E24="Sim", O24*$G$3,0) -> 0 | Q24: =IF(E24="Não",0, O24+(O24*$M$4)+P24 ) -> #N/A | R24: =Q24/$G$2 -> #N/A | S24: =IF(C24="CLT", H24*$K$2, 0) -> 0 | T24: =IF(C24="CLT", S24*$K$3, 0) -> 0 | U24: =IF(C24="CLT", H24/12, 0) -> 0 | V24: =IF(C24="CLT", U24/3, 0) -> 0 | W24: =IF(C24="CLT", H24/12, 0) -> 0 | X24: =IF(C24="CLT", H24/12, 0) -> 0 | Y24: =IF(B24<>"", IF(C24="CLT", 22*$K$5,0),0) -> 0 | Z24: =IF(C24="CLT", H24*$K$4, 0) -> 0 | AA24: =IF(B24<>"", IF(C24="CLT", $O$2, 0),0) -> 0 | AB24: =SUM(S24:AA24) -> 0 | AC24: =IF(E24="Sim", Q24*$G$4, 0) -> 0 | AD24: =Q24-AC24-I24-M24-P24 -> #N/A | AE24: =(IF(AD24>0,AD24/Q24,"")) -> #N/A
C25: PJ | F25: 0 | G25: =IF(F25>0,F25, IF(B25<>"", IF(C25="CLT",VLOOKUP(B25,'Lista Profissionais'!$C$11:$H$348,3,0), VLOOKUP(B25,'Lista Profissionais'!$C$11:$H$348,4,0)), 0)) -> 0 | H25: =(G25/$G$2)*D25 -> 0 | I25: =H25+AB25 -> 0 | J25: =I25+AC25 -> 0 | K25: 0 | L25: 0 | M25: =I25*$G$6 -> 0 | N25: =IF(K25>0,K25, IF(L25>0,(G25*(1+L25)+M25), (G25*(1+$G$5)+M25))) -> 0 | O25: =(N25/$G$2)*D25 -> 0 | P25: =IF(E25="Sim", O25*$G$3,0) -> 0 | Q25: =IF(E25="Não",0, O25+(O25*$M$4)+P25 ) -> #N/A | R25: =Q25/$G$2 -> #N/A | S25: =IF(C25="CLT", H25*$K$2, 0) -> 0 | T25: =IF(C25="CLT", S25*$K$3, 0) -> 0 | U25: =IF(C25="CLT", H25/12, 0) -> 0 | V25: =IF(C25="CLT", U25/3, 0) -> 0 | W25: =IF(C25="CLT", H25/12, 0) -> 0 | X25: =IF(C25="CLT", H25/12, 0) -> 0 | Y25: =IF(B25<>"", IF(C25="CLT", 22*$K$5,0),0) -> 0 | Z25: =IF(C25="CLT", H25*$K$4, 0) -> 0 | AA25: =IF(B25<>"", IF(C25="CLT", $O$2, 0),0) -> 0 | AB25: =SUM(S25:AA25) -> 0 | AC25: =IF(E25="Sim", Q25*$G$4, 0) -> 0 | AD25: =Q25-AC25-I25-M25-P25 -> #N/A | AE25: =(IF(AD25>0,AD25/Q25,"")) -> #N/A
C26: PJ | F26: 0 | G26: =IF(F26>0,F26, IF(B26<>"", IF(C26="CLT",VLOOKUP(B26,'Lista Profissionais'!$C$11:$H$348,3,0), VLOOKUP(B26,'Lista Profissionais'!$C$11:$H$348,4,0)), 0)) -> 0 | H26: =(G26/$G$2)*D26 -> 0 | I26: =H26+AB26 -> 0 | J26: =I26+AC26 -> 0 | K26: 0 | L26: 0 | M26: =I26*$G$6 -> 0 | N26: =IF(K26>0,K26, IF(L26>0,(G26*(1+L26)+M26), (G26*(1+$G$5)+M26))) -> 0 | O26: =(N26/$G$2)*D26 -> 0 | P26: =IF(E26="Sim", O26*$G$3,0) -> 0 | Q26: =IF(E26="Não",0, O26+(O26*$M$4)+P26 ) -> #N/A | R26: =Q26/$G$2 -> #N/A | S26: =IF(C26="CLT", H26*$K$2, 0) -> 0 | T26: =IF(C26="CLT", S26*$K$3, 0) -> 0 | U26: =IF(C26="CLT", H26/12, 0) -> 0 | V26: =IF(C26="CLT", U26/3, 0) -> 0 | W26: =IF(C26="CLT", H26/12, 0) -> 0 | X26: =IF(C26="CLT", H26/12, 0) -> 0 | Y26: =IF(B26<>"", IF(C26="CLT", 22*$K$5,0),0) -> 0 | Z26: =IF(C26="CLT", H26*$K$4, 0) -> 0 | AA26: =IF(B26<>"", IF(C26="CLT", $O$2, 0),0) -> 0 | AB26: =SUM(S26:AA26) -> 0 | AC26: =IF(E26="Sim", Q26*$G$4, 0) -> 0 | AD26: =Q26-AC26-I26-M26-P26 -> #N/A | AE26: =(IF(AD26>0,AD26/Q26,"")) -> #N/A
... C33: PJ | F33: 0 | G33: =IF(F33>0,F33, IF(B33<>"", IF(C33="CLT",VLOOKUP(B33,'Lista Profissionais'!$C$11:$H$348,3,0), VLOOKUP(B33,'Lista Profissionais'!$C$11:$H$348,4,0)), 0)) -> 0 | H33: =(G33/$G$2)*D33 -> 0 | I33: =H33+AB33 -> 0 | J33: =I33+AC33 -> 0 | K33: 0 | L33: 0 | M33: =I33*$G$6 -> 0 | N33: =IF(K33>0,K33, IF(L33>0,(G33*(1+L33)+M33), (G33*(1+$G$5)+M33))) -> 0 | O33: =(N33/$G$2)*D33 -> 0 | P33: =IF(E33="Sim", O33*$G$3,0) -> 0 | Q33: =IF(E33="Não",0, O33+(O33*$M$4)+P33 ) -> #N/A | R33: =Q33/$G$2 -> #N/A | S33: =IF(C33="CLT", H33*$K$2, 0) -> 0 | T33: =IF(C33="CLT", S33*$K$3, 0) -> 0 | U33: =IF(C33="CLT", H33/12, 0) -> 0 | V33: =IF(C33="CLT", U33/3, 0) -> 0 | W33: =IF(C33="CLT", H33/12, 0) -> 0 | X33: =IF(C33="CLT", H33/12, 0) -> 0 | Y33: =IF(B33<>"", IF(C33="CLT", 22*$K$5,0),0) -> 0 | Z33: =IF(C33="CLT", H33*$K$4, 0) -> 0 | AA33: =IF(B33<>"", IF(C33="CLT", $O$2, 0),0) -> 0 | AB33: =SUM(S33:AA33) -> 0 | AC33: =IF(E33="Sim", Q33*$G$4, 0) -> 0 | AD33: =Q33-AC33-I33-M33-P33 -> #N/A | AE33: =(IF(AD33>0,AD33/Q33,"")) -> #N/A
O37: Q | P37: P | Q37: I | S37: M | T37: AB
O38: Tarifa com rateio | P38: Comissão | Q38: Salario | S38: Risco | T38: Imposto | U38: Custo | V38: Lucro
O39: =Q9 -> 0 | P39: =P9 -> 0 | Q39: =I9 -> #N/A | S39: =M9 -> #N/A | T39: =AC9 -> 0 | U39: =SUBTOTAL(9,P39:T39) -> #N/A | V39: =O39-U39 -> #N/A
O40: =Q10 -> #N/A | P40: =P10 -> #N/A | Q40: =I10 -> #N/A | S40: =M10 -> #N/A | T40: =AC10 -> #N/A | U40: =SUBTOTAL(9,P40:T40) -> #N/A | V40: =O40-U40 -> #N/A
O41: =Q11 -> #N/A | P41: =P11 -> #N/A | Q41: =I11 -> #N/A | S41: =M11 -> #N/A | T41: =AC11 -> #N/A | U41: =SUBTOTAL(9,P41:T41) -> #N/A | V41: =O41-U41 -> #N/A
O42: =Q12 -> #N/A | P42: =P12 -> #N/A | Q42: =I12 -> #N/A | S42: =M12 -> #N/A | T42: =AC12 -> #N/A | U42: =SUBTOTAL(9,P42:T42) -> #N/A | V42: =O42-U42 -> #N/A
O43: =Q13 -> #N/A | P43: =P13 -> #N/A | Q43: =I13 -> #N/A | S43: =M13 -> #N/A | T43: =AC13 -> #N/A | U43: =SUBTOTAL(9,P43:T43) -> #N/A | V43: =O43-U43 -> #N/A
O44: =Q14 -> #N/A | P44: =P14 -> #N/A | Q44: =I14 -> #N/A | S44: =M14 -> #N/A | T44: =AC14 -> #N/A | U44: =SUBTOTAL(9,P44:T44) -> #N/A | V44: =O44-U44 -> #N/A
O45: =SUM(O39:O44) -> #N/A | P45: =SUM(P39:P44) -> #N/A | Q45: =SUM(Q39:Q44) -> #N/A | S45: =SUM(S39:S44) -> #N/A | T45: =SUM(T39:T44) -> #N/A | U45: =SUBTOTAL(9,P45:T45) -> #N/A | V45: =O45-U45 -> #N/A

Sheet Lista Profissionais
B1: Composição de preços (CLT e PJ)
B3: Diferença de CLT para PJ | D3: Júnior | E3: 0.3
D4: Pleno | E4: 0.3
D5: Sênior | E5: 0.3 | L5: Dif. Alta | M5: =COUNTIF(M11:M526,"Alta") -> 0
D6: Automatizador | E6: 0.3 | L6: Dif. Média | M6: =COUNTIF(M11:M526,"Média") -> 0
B7: Utilizar valores da Tabela | C7: AVN | D7: Especialista | E7: 0.3 | L7: Dif. Baixa | M7: =COUNTIF(M11:M526,"Baixa") -> 0
D8: Agilista | E8: 0.3
D9: Gestão | E9: 0.3 | G9: 0.2 | I9: BASE | L9: % Dif | O9: Definição | P9: FONTE PESQUISA
B10: Especialidade | C10: Perfil | D10: Senioridade | E10: CLT | F10: Base CLT | G10: Redução benefício | H10: PJ | I10: Mínimo CLT | J10: Média CLT | K10: Máximo CLT | L10: % | M10: Diferença | N10: Enviar | O10: AVN | P10: TECH HUB | Q10: TALENT | R10: GLASS DOR | S10: ROBERT HALF | T10: CATHO
B11: Administrador/Consultor Salesforce - Especialista | C11: =B11 -> Administrador/Consultor Salesforce - Especialista | D11: Especialista | E11: =F11-G11 -> 9600 | F11: 12000 | G11: =F11*$G$9 -> 2400 | H11: =E11+(E11*IF(D11<>"",IF(D11<>"",VLOOKUP(D11,$D$3:$E$9,2,0)),"")) -> 12480 | I11: =_xlfn.MINIFS(Q11:T11,Q11:T11,">0",Q11:T11,"<>"&"") -> #NAME? | J11: =IF(SUM(Q11:T11)>0, AVERAGEIFS(Q11:T11, Q11:T11,">0",Q11:T11,"<>"&""), 0) -> 11525.985 | K11: =_xlfn.MAXIFS(Q11:T11,Q11:T11,">0",Q11:T11,"<>"&"") -> #NAME? | L11: =(K11-I11)/I11 -> #NAME? | M11: {=_xlfn.IFS(L11>=70%,"Alta",L11>20%,"Média",L11<=20%,"Baixa")} -> #NAME? | O11: =J11 -> 11525.985 | P11: 0 | Q11: 11051.97 | R11: 12000 | S11: 0 | T11: 0
B12: Administrador/Consultor Salesforce - Junior | C12: =B12 -> Administrador/Consultor Salesforce - Junior | D12: Júnior | E12: =F12-G12 -> 3040 | F12: 3800 | G12: =F12*$G$9 -> 760 | H12: =E12+(E12*IF(D12<>"",IF(D12<>"",VLOOKUP(D12,$D$3:$E$9,2,0)),"")) -> 3952 | I12: =_xlfn.MINIFS(Q12:T12,Q12:T12,">0",Q12:T12,"<>"&"") -> #NAME? | J12: =IF(SUM(Q12:T12)>0, AVERAGEIFS(Q12:T12, Q12:T12,">0",Q12:T12,"<>"&""), 0) -> 4906.5 | K12: =_xlfn.MAXIFS(Q12:T12,Q12:T12,">0",Q12:T12,"<>"&"") -> #NAME? | L12: =(K12-I12)/I12 -> #NAME? | M12: {=_xlfn.IFS(L12>=70%,"Alta",L12>20%,"Média",L12<=20%,"Baixa")} -> #NAME? | O12: =J12 -> 4906.5 | P12: =K12 -> #NAME? | Q12: 5813 | R12: 4000 | S12: 0 | T12: 0
B13: Administrador/Consultor Salesforce - Pleno | C13: =B13 -> Administrador/Consultor Salesforce - Pleno | D13: Pleno | E13: =F13-G13 -> 6320 | F13: 7900 | G13: =F13*$G$9 -> 1580 | H13: =E13+(E13*IF(D13<>"",IF(D13<>"",VLOOKUP(D13,$D$3:$E$9,2,0)),"")) -> 8216 | I13: =_xlfn.MINIFS(Q13:T13,Q13:T13,">0",Q13:T13,"<>"&"") -> #NAME? | J13: =IF(SUM(Q13:T13)>0, AVERAGEIFS(Q13:T13, Q13:T13,">0",Q13:T13,"<>"&""), 0) -> 7278.45 | K13: =_xlfn.MAXIFS(Q13:T13,Q13:T13,">0",Q13:T13,"<>"&"") -> #NAME? | L13: =(K13-I13)/I13 -> #NAME? | M13: {=_xlfn.IFS(L13>=70%,"Alta",L13>20%,"Média",L13<=20%,"Baixa")} -> #NAME? | O13: =J13 -> 7278.45 | P13: 0 | Q13: 7556.9 | R13: 7000 | S13: 0 | T13: 0
B14: Administrador/Consultor Salesforce - Senior | C14: =B14 -> Administrador/Consultor Salesforce - Senior | D14: Sênior | E14: =F14-G14 -> 8400 | F14: 10500 | G14: =F14*$G$9 -> 2100 | H14: =E14+(E14*IF(D14<>"",IF(D14<>"",VLOOKUP(D14,$D$3:$E$9,2,0)),"")) -> 10920 | I14: =_xlfn.MINIFS(Q14:T14,Q14:T14,">0",Q14:T14,"<>"&"") -> #NAME? | J14: =IF(SUM(Q14:T14)>0, AVERAGEIFS(Q14:T14, Q14:T14,">0",Q14:T14,"<>"&""), 0) -> 9723.0625 | K14: =_xlfn.MAXIFS(Q14:T14,Q14:T14,">0",Q14:T14,"<>"&"") -> #NAME? | L14: =(K14-I14)/I14 -> #NAME? | M14: {=_xlfn.IFS(L14>=70%,"Alta",L14>20%,"Média",L14<=20%,"Baixa")} -> #NAME? | O14: =J14 -> 9723.0625 | P14: 0 | Q14: 9446.125 | R14: 10000 | S14: 0 | T14: 0
B15: Agilista | C15: =B15& " " &D15 -> Agilista Especialista | D15: Especialista | E15: =F15-G15 -> 10800 | F15: 13500 | G15: =F15*$G$9 -> 2700 | H15: =F15+(F15*IF(D15<>"",IF(D15<>"",VLOOKUP(D15,$D$3:$F$9,2,0)),"")) -> 17550 | I15: =_xlfn.MINIFS(Q15:T15,Q15:T15,">0",Q15:T15,"<>"&"") -> #NAME? | J15: =IF(SUM(Q15:T15)>0, AVERAGEIFS(Q15:T15, Q15:T15,">0",Q15:T15,"<>"&""), 0) -> 10122.875 | K15: =_xlfn.MAXIFS(Q15:T15,Q15:T15,">0",Q15:T15,"<>"&"") -> #NAME? | L15: =(K15-I15)/I15 -> #NAME? | M15: {=_xlfn.IFS(L15>=70%,"Alta",L15>20%,"Média",L15<=20%,"Baixa")} -> #NAME? | N15: SIM | O15: =J15 -> 10122.875 | P15: 0 | Q15: 8745.75 | R15: 11500 | S15: 0 | T15: 0
B16: Agilista - Junior | C16: =B16& " " &D16 -> Agilista - Junior Júnior | D16: Júnior | E16: =F16-G16 -> 3920 | F16: 4900 | G16: =F16*$G$9 -> 980 | H16: =F16+(F16*IF(D16<>"",IF(D16<>"",VLOOKUP(D16,$D$3:$F$9,2,0)),"")) -> 6370 | I16: =_xlfn.MINIFS(Q16:T16,Q16:T16,">0",Q16:T16,"<>"&"") -> #NAME? | J16: =IF(SUM(Q16:T16)>0, AVERAGEIFS(Q16:T16, Q16:T16,">0",Q16:T16,"<>"&""), 0) -> 4300 | K16: =_xlfn.MAXIFS(Q16:T16,Q16:T16,">0",Q16:T16,"<>"&"") -> #NAME? | L16: =(K16-I16)/I16 -> #NAME? | M16: {=_xlfn.IFS(L16>=70%,"Alta",L16>20%,"Média",L16<=20%,"Baixa")} -> #NAME? | N16: SIM | O16: =J16 -> 4300 | P16: 0 | Q16: 4600 | R16: 4000 | S16: 0 | T16: 0
B17: Agilista | C17: =B17& " " &D17 -> Agilista Pleno | D17: Pleno | E17: =F17-G17 -> 6320 | F17: 7900 | G17: =F17*$G$9 -> 1580 | H17: =F17+(F17*IF(D17<>"",IF(D17<>"",VLOOKUP(D17,$D$3:$F$9,2,0)),"")) -> 10270 | I17: =_xlfn.MINIFS(Q17:T17,Q17:T17,">0",Q17:T17,"<>"&"") -> #NAME? | J17: =IF(SUM(Q17:T17)>0, AVERAGEIFS(Q17:T17, Q17:T17,">0",Q17:T17,"<>"&""), 0) -> 6490 | K17: =_xlfn.MAXIFS(Q17:T17,Q17:T17,">0",Q17:T17,"<>"&"") -> #NAME? | L17: =(K17-I17)/I17 -> #NAME? | M17: {=_xlfn.IFS(L17>=70%,"Alta",L17>20%,"Média",L17<=20%,"Baixa")} -> #NAME? | N17: SIM | O17: =J17 -> 6490 | P17: 0 | Q17: 5980 | R17: 7000 | S17: 0 | T17: 0
B18: Agilista | C18: =B18& " " &D18 -> Agilista Sênior | D18: Sênior | E18: =F18-G18 -> 9200 | F18: 11500 | G18: =F18*$G$9 -> 2300 | H18: =F18+(F18*IF(D18<>"",IF(D18<>"",VLOOKUP(D18,$D$3:$F$9,2,0)),"")) -> 14950 | I18: =_xlfn.MINIFS(Q18:T18,Q18:T18,">0",Q18:T18,"<>"&"") -> #NAME? | J18: =IF(SUM(Q18:T18)>0, AVERAGEIFS(Q18:T18, Q18:T18,">0",Q18:T18,"<>"&""), 0) -> 8487.5 | K18: =_xlfn.MAXIFS(Q18:T18,Q18:T18,">0",Q18:T18,"<>"&"") -> #NAME? | L18: =(K18-I18)/I18 -> #NAME? | M18: {=_xlfn.IFS(L18>=70%,"Alta",L18>20%,"Média",L18<=20%,"Baixa")} -> #NAME? | N18: SIM | O18: =J18 -> 8487.5 | P18: 0 | Q18: 7475 | R18: 9500 | S18: 0 | T18: 0
B19: Analista de Dados/ BI | C19: =B19& " " &D19 -> Analista de Dados/ BI Especialista | D19: Especialista | E19: =F19-G19 -> 8800 | F19: 11000 | G19: =F19*$G$9 -> 2200 | H19: =F19+(F19*IF(D19<>"",IF(D19<>"",VLOOKUP(D19,$D$3:$F$9,2,0)),"")) -> 14300 | I19: =_xlfn.MINIFS(Q19:T19,Q19:T19,">0",Q19:T19,"<>"&"") -> #NAME? | J19: =IF(SUM(Q19:T19)>0, AVERAGEIFS(Q19:T19, Q19:T19,">0",Q19:T19,"<>"&""), 0) -> 10200 | K19: =_xlfn.MAXIFS(Q19:T19,Q19:T19,">0",Q19:T19,"<>"&"") -> #NAME? | L19: =(K19-I19)/I19 -> #NAME? | M19: {=_xlfn.IFS(L19>=70%,"Alta",L19>20%,"Média",L19<=20%,"Baixa")} -> #NAME? | N19: SIM | O19: =J19 -> 10200 | P19: 0 | Q19: 9400 | R19: 11000 | S19: 0 | T19: 0
B20: Analista de Dados/ BI | C20: =B20& " " &D20 -> Analista de Dados/ BI Júnior | D20: Júnior | E20: =F20-G20 -> 3360 | F20: 4200 | G20: =F20*$G$9 -> 840 | H20: =F20+(F20*IF(D20<>"",IF(D20<>"",VLOOKUP(D20,$D$3:$F$9,2,0)),"")) -> 5460 | I20: =_xlfn.MINIFS(Q20:T20,Q20:T20,">0",Q20:T20,"<>"&"") -> #NAME? | J20: =IF(SUM(Q20:T20)>0, AVERAGEIFS(Q20:T20, Q20:T20,">0",Q20:T20,"<>"&""), 0) -> 3519 | K20: =_xlfn.MAXIFS(Q20:T20,Q20:T20,">0",Q20:T20,"<>"&"") -> #NAME? | L20: =(K20-I20)/I20 -> #NAME? | M20: {=_xlfn.IFS(L20>=70%,"Alta",L20>20%,"Média",L20<=20%,"Baixa")} -> #NAME? | N20: SIM | O20: =J20 -> 3519 | P20: 0 | Q20: 4538 | R20: 2500 | S20: 0 | T20: 0
B21: Analista de Dados/ BI | C21: =B21& " " &D21 -> Analista de Dados/ BI Pleno | D21: Pleno | E21: =F21-G21 -> 6000 | F21: 7500 | G21: =F21*$G$9 -> 1500 | H21: =F21+(F21*IF(D21<>"",IF(D21<>"",VLOOKUP(D21,$D$3:$F$9,2,0)),"")) -> 9750 | I21: =_xlfn.MINIFS(Q21:T21,Q21:T21,">0",Q21:T21,"<>"&"") -> #NAME? | J21: =IF(SUM(Q21:T21)>0, AVERAGEIFS(Q21:T21, Q21:T21,">0",Q21:T21,"<>"&""), 0) -> 6000 | K21: =_xlfn.MAXIFS(Q21:T21,Q21:T21,">0",Q21:T21,"<>"&"") -> #NAME? | L21: =(K21-I21)/I21 -> #NAME? | M21: {=_xlfn.IFS(L21>=70%,"Alta",L21>20%,"Média",L21<=20%,"Baixa")} -> #NAME? | N21: SIM | O21: =J21 -> 6000 | P21: 0 | Q21: 6500 | R21: 5500 | S21: 0 | T21: 0
B22: Analista de Dados/ BI | C22: =B22& " " &D22 -> Analista de Dados/ BI Sênior | D22: Sênior | E22: =F22-G22 -> 7600 | F22: 9500 | G22: =F22*$G$9 -> 1900 | H22: =F22+(F22*IF(D22<>"",IF(D22<>"",VLOOKUP(D22,$D$3:$F$9,2,0)),"")) -> 12350 | I22: =_xlfn.MINIFS(Q22:T22,Q22:T22,">0",Q22:T22,"<>"&"") -> #NAME? | J22: =IF(SUM(Q22:T22)>0, AVERAGEIFS(Q22:T22, Q22:T22,">0",Q22:T22,"<>"&""), 0) -> 8125 | K22: =_xlfn.MAXIFS(Q22:T22,Q22:T22,">0",Q22:T22,"<>"&"") -> #NAME? | L22: =(K22-I22)/I22 -> #NAME? | M22: {=_xlfn.IFS(L22>=70%,"Alta",L22>20%,"Média",L22<=20%,"Baixa")} -> #NAME? | N22: SIM | O22: =J22 -> 8125 | P22: 0 | Q22: 8250 | R22: 8000 | S22: 0 | T22: 0
B23: Analista de Inteligência Artificial | C23: =B23& " " &D23 -> Analista de Inteligência Artificial Especialista | D23: Especialista | E23: =F23-G23 -> 10800 | F23: 13500 | G23: =F23*$G$9 -> 2700 | H23: =F23+(F23*IF(D23<>"",IF(D23<>"",VLOOKUP(D23,$D$3:$F$9,2,0)),"")) -> 17550 | I23: =_xlfn.MINIFS(Q23:T23,Q23:T23,">0",Q23:T23,"<>"&"") -> #NAME? | J23: =IF(SUM(Q23:T23)>0, AVERAGEIFS(Q23:T23, Q23:T23,">0",Q23:T23,"<>"&""), 0) -> 10396.641 | K23: =_xlfn.MAXIFS(Q23:T23,Q23:T23,">0",Q23:T23,"<>"&"") -> #NAME? | L23: =(K23-I23)/I23 -> #NAME? | M23: {=_xlfn.IFS(L23>=70%,"Alta",L23>20%,"Média",L23<=20%,"Baixa")} -> #NAME? | N23: SIM | O23: =J23 -> 10396.641 | P23: 0 | Q23: 8793.2812 | R23: 12000 | S23: 0 | T23: 0
B24: Analista de Inteligência Artificial | C24: =B24& " " &D24 -> Analista de Inteligência Artificial Júnior | D24: Júnior | E24: =F24-G24 -> 3920 | F24: 4900 | G24: =F24*$G$9 -> 980 | H24: =F24+(F24*IF(D24<>"",IF(D24<>"",VLOOKUP(D24,$D$3:$F$9,2,0)),"")) -> 6370 | I24: =_xlfn.MINIFS(Q24:T24,Q24:T24,">0",Q24:T24,"<>"&"") -> #NAME? | J24: =IF(SUM(Q24:T24)>0, AVERAGEIFS(Q24:T24, Q24:T24,">0",Q24:T24,"<>"&""), 0) -> 4400 | K24: =_xlfn.MAXIFS(Q24:T24,Q24:T24,">0",Q24:T24,"<>"&"") -> #NAME? | L24: =(K24-I24)/I24 -> #NAME? | M24: {=_xlfn.IFS(L24>=70%,"Alta",L24>20%,"Média",L24<=20%,"Baixa")} -> #NAME? | N24: SIM | O24: =J24 -> 4400 | P24: 0 | Q24: 5300 | R24: 3500 | S24: 0 | T24: 0
B25: Analista de Inteligência Artificial | C25: =B25& " " &D25 -> Analista de Inteligência Artificial Pleno | D25: Pleno | E25: =F25-G25 -> 6000 | F25: 7500 | G25: =F25*$G$9 -> 1500 | H25: =F25+(F25*IF(D25<>"",IF(D25<>"",VLOOKUP(D25,$D$3:$F$9,2,0)),"")) -> 9750 | I25: =_xlfn.MINIFS(Q25:T25,Q25:T25,">0",Q25:T25,"<>"&"") -> #NAME? | J25: =IF(SUM(Q25:T25)>0, AVERAGEIFS(Q25:T25, Q25:T25,">0",Q25:T25,"<>"&""), 0) -> 6506.25 | K25: =_xlfn.MAXIFS(Q25:T25,Q25:T25,">0",Q25:T25,"<>"&"") -> #NAME? | L25: =(K25-I25)/I25 -> #NAME? | M25: {=_xlfn.IFS(L25>=70%,"Alta",L25>20%,"Média",L25<=20%,"Baixa")} -> #NAME? | N25: SIM | O25: =J25 -> 6506.25 | P25: 0 | Q25: 6012.5 | R25: 7000 | S25: 0 | T25: 0
B26: Analista de Inteligência Artificial | C26: =B26& " " &D26 -> Analista de Inteligência Artificial Sênior | D26: Sênior | E26: =F26-G26 -> 8800 | F26: 11000 | G26: =F26*$G$9 -> 2200 | H26: =F26+(F26*IF(D26<>"",IF(D26<>"",VLOOKUP(D26,$D$3:$F$9,2,0)),"")) -> 14300 | I26: =_xlfn.MINIFS(Q26:T26,Q26:T26,">0",Q26:T26,"<>"&"") -> #NAME? | J26: =IF(SUM(Q26:T26)>0, AVERAGEIFS(Q26:T26, Q26:T26,">0",Q26:T26,"<>"&""), 0) -> 8757.8125 | K26: =_xlfn.MAXIFS(Q26:T26,Q26:T26,">0",Q26:T26,"<>"&"") -> #NAME? | L26: =(K26-I26)/I26 -> #NAME? | M26: {=_xlfn.IFS(L26>=70%,"Alta",L26>20%,"Média",L26<=20%,"Baixa")} -> #NAME? | N26: SIM | O26: =J26 -> 8757.8125 | P26: 0 | Q26: 7515.625 | R26: 10000 | S26: 0 | T26: 0
... B30: Analista de Processos | C30: =B30& " " &D30 -> Analista de Processos Sênior | D30: Sênior | E30: =F30-G30 -> 8000 | F30: 10000 | G30: =F30*$G$9 -> 2000 | H30: =F30+(F30*IF(D30<>"",IF(D30<>"",VLOOKUP(D30,$D$3:$F$9,2,0)),"")) -> 13000 | I30: =_xlfn.MINIFS(Q30:T30,Q30:T30,">0",Q30:T30,"<>"&"") -> #NAME? | J30: =IF(SUM(Q30:T30)>0, AVERAGEIFS(Q30:T30, Q30:T30,">0",Q30:T30,"<>"&""), 0) -> 7250 | K30: =_xlfn.MAXIFS(Q30:T30,Q30:T30,">0",Q30:T30,"<>"&"") -> #NAME? | L30: =(K30-I30)/I30 -> #NAME? | M30: {=_xlfn.IFS(L30>=70%,"Alta",L30>20%,"Média",L30<=20%,"Baixa")} -> #NAME? | N30: SIM | O30: =J30 -> 7250 | P30: 0 | Q30: 6500 | R30: 8000 | S30: 0 | T30: 0
B31: Analista de Qualidade | C31: =B31& " " &D31 -> Analista de Qualidade Especialista | D31: Especialista | E31: =F31-G31 -> 8000 | F31: 10000 | G31: =F31*$G$9 -> 2000 | H31: =F31+(F31*IF(D31<>"",IF(D31<>"",VLOOKUP(D31,$D$3:$F$9,2,0)),"")) -> 13000 | I31: =_xlfn.MINIFS(Q31:T31,Q31:T31,">0",Q31:T31,"<>"&"") -> #NAME? | J31: =IF(SUM(Q31:T31)>0, AVERAGEIFS(Q31:T31, Q31:T31,">0",Q31:T31,"<>"&""), 0) -> 8552.5 | K31: =_xlfn.MAXIFS(Q31:T31,Q31:T31,">0",Q31:T31,"<>"&"") -> #NAME? | L31: =(K31-I31)/I31 -> #NAME? | M31: {=_xlfn.IFS(L31>=70%,"Alta",L31>20%,"Média",L31<=20%,"Baixa")} -> #NAME? | N31: SIM | O31: 8300 | P31: 0 | Q31: 7605 | R31: 9500 | S31: 0 | T31: 0
B32: Analista de Qualidade | C32: =B32& " " &D32 -> Analista de Qualidade Júnior | D32: Júnior | E32: =F32-G32 -> 2800 | F32: 3500 | G32: =F32*$G$9 -> 700 | H32: =F32+(F32*IF(D32<>"",IF(D32<>"",VLOOKUP(D32,$D$3:$F$9,2,0)),"")) -> 4550 | I32: =_xlfn.MINIFS(Q32:T32,Q32:T32,">0",Q32:T32,"<>"&"") -> #NAME? | J32: =IF(SUM(Q32:T32)>0, AVERAGEIFS(Q32:T32, Q32:T32,">0",Q32:T32,"<>"&""), 0) -> 3500 | K32: =_xlfn.MAXIFS(Q32:T32,Q32:T32,">0",Q32:T32,"<>"&"") -> #NAME? | L32: =(K32-I32)/I32 -> #NAME? | M32: {=_xlfn.IFS(L32>=70%,"Alta",L32>20%,"Média",L32<=20%,"Baixa")} -> #NAME? | N32: SIM | O32: =J32 -> 3500 | P32: 0 | Q32: 4000 | R32: 3000 | S32: 0 | T32: 0
B33: Analista de Qualidade | C33: =B33& " " &D33 -> Analista de Qualidade Pleno | D33: Pleno | E33: =F33-G33 -> 4400 | F33: 5500 | G33: =F33*$G$9 -> 1100 | H33: =F33+(F33*IF(D33<>"",IF(D33<>"",VLOOKUP(D33,$D$3:$F$9,2,0)),"")) -> 7150 | I33: =_xlfn.MINIFS(Q33:T33,Q33:T33,">0",Q33:T33,"<>"&"") -> #NAME? | J33: =IF(SUM(Q33:T33)>0, AVERAGEIFS(Q33:T33, Q33:T33,">0",Q33:T33,"<>"&""), 0) -> 6100 | K33: =_xlfn.MAXIFS(Q33:T33,Q33:T33,">0",Q33:T33,"<>"&"") -> #NAME? | L33: =(K33-I33)/I33 -> #NAME? | M33: {=_xlfn.IFS(L33>=70%,"Alta",L33>20%,"Média",L33<=20%,"Baixa")} -> #NAME? | N33: SIM | O33: =J33 -> 6100 | P33: 0 | Q33: 5200 | R33: 7000 | S33: 0 | T33: 0
B34: Analista de Qualidade | C34: =B34& " " &D34 -> Analista de Qualidade Sênior | D34: Sênior | E34: =F34-G34 -> 5416 | F34: 6770 | G34: =F34*$G$9 -> 1354 | H34: =F34+(F34*IF(D34<>"",IF(D34<>"",VLOOKUP(D34,$D$3:$F$9,2,0)),"")) -> 8801 | I34: =_xlfn.MINIFS(Q34:T34,Q34:T34,">0",Q34:T34,"<>"&"") -> #NAME? | J34: =IF(SUM(Q34:T34)>0, AVERAGEIFS(Q34:T34, Q34:T34,">0",Q34:T34,"<>"&""), 0) -> 7500 | K34: =_xlfn.MAXIFS(Q34:T34,Q34:T34,">0",Q34:T34,"<>"&"") -> #NAME? | L34: =(K34-I34)/I34 -> #NAME? | M34: {=_xlfn.IFS(L34>=70%,"Alta",L34>20%,"Média",L34<=20%,"Baixa")} -> #NAME? | N34: SIM | O34: =J34 -> 7500 | P34: 0 | Q34: 6500 | R34: 8500 | S34: 0 | T34: 0
B35: Analista de Negócios | C35: =B35& " " &D35 -> Analista de Negócios Especialista | D35: Especialista | E35: =F35-G35 -> 8400 | F35: 10500 | G35: =F35*$G$9 -> 2100 | H35: =F35+(F35*IF(D35<>"",IF(D35<>"",VLOOKUP(D35,$D$3:$F$9,2,0)),"")) -> 13650 | I35: =_xlfn.MINIFS(Q35:T35,Q35:T35,">0",Q35:T35,"<>"&"") -> #NAME? | J35: =IF(SUM(Q35:T35)>0, AVERAGEIFS(Q35:T35, Q35:T35,">0",Q35:T35,"<>"&""), 0) -> 9323.5 | K35: =_xlfn.MAXIFS(Q35:T35,Q35:T35,">0",Q35:T35,"<>"&"") -> #NAME? | L35: =(K35-I35)/I35 -> #NAME? | M35: {=_xlfn.IFS(L35>=70%,"Alta",L35>20%,"Média",L35<=20%,"Baixa")} -> #NAME? | N35: SIM | O35: =J35 -> 9323.5 | P35: 0 | Q35: 10647 | R35: 8000 | S35: 0 | T35: 0
B36: Analista de Negócios | C36: =B36& " " &D36 -> Analista de Negócios Júnior | D36: Júnior | E36: =F36-G36 -> 3840 | F36: 4800 | G36: =F36*$G$9 -> 960 | H36: =F36+(F36*IF(D36<>"",IF(D36<>"",VLOOKUP(D36,$D$3:$F$9,2,0)),"")) -> 6240 | I36: =_xlfn.MINIFS(Q36:T36,Q36:T36,">0",Q36:T36,"<>"&"") -> #NAME? | J36: =IF(SUM(Q36:T36)>0, AVERAGEIFS(Q36:T36, Q36:T36,">0",Q36:T36,"<>"&""), 0) -> 4550 | K36: =_xlfn.MAXIFS(Q36:T36,Q36:T36,">0",Q36:T36,"<>"&"") -> #NAME? | L36: =(K36-I36)/I36 -> #NAME? | M36: {=_xlfn.IFS(L36>=70%,"Alta",L36>20%,"Média",L36<=20%,"Baixa")} -> #NAME? | N36: SIM | O36: =J36 -> 4550 | P36: 0 | Q36: 5600 | R36: 3500 | S36: 0 | T36: 0
B37: Analista de Negócios | C37: =B37& " " &D37 -> Analista de Negócios Pleno | D37: Pleno | E37: =F37-G37 -> 6000 | F37: 7500 | G37: =F37*$G$9 -> 1500 | H37: =F37+(F37*IF(D37<>"",IF(D37<>"",VLOOKUP(D37,$D$3:$F$9,2,0)),"")) -> 9750 | I37: =_xlfn.MINIFS(Q37:T37,Q37:T37,">0",Q37:T37,"<>"&"") -> #NAME? | J37: =IF(SUM(Q37:T37)>0, AVERAGEIFS(Q37:T37, Q37:T37,">0",Q37:T37,"<>"&""), 0) -> 6540 | K37: =_xlfn.MAXIFS(Q37:T37,Q37:T37,">0",Q37:T37,"<>"&"") -> #NAME? | L37: =(K37-I37)/I37 -> #NAME? | M37: {=_xlfn.IFS(L37>=70%,"Alta",L37>20%,"Média",L37<=20%,"Baixa")} -> #NAME? | N37: SIM | O37: =J37 -> 6540 | P37: 0 | Q37: 7280 | R37: 5800 | S37: 0 | T37: 0
B38: Analista de Negócios | C38: =B38& " " &D38 -> Analista de Negócios Sênior | D38: Sênior | E38: =F38-G38 -> 8400 | F38: 10500 | G38: =F38*$G$9 -> 2100 | H38: =F38+(F38*IF(D38<>"",IF(D38<>"",VLOOKUP(D38,$D$3:$F$9,2,0)),"")) -> 13650 | I38: =_xlfn.MINIFS(Q38:T38,Q38:T38,">0",Q38:T38,"<>"&"") -> #NAME? | J38: =IF(SUM(Q38:T38)>0, AVERAGEIFS(Q38:T38, Q38:T38,">0",Q38:T38,"<>"&""), 0) -> 8050 | K38: =_xlfn.MAXIFS(Q38:T38,Q38:T38,">0",Q38:T38,"<>"&"") -> #NAME? | L38: =(K38-I38)/I38 -> #NAME? | M38: {=_xlfn.IFS(L38>=70%,"Alta",L38>20%,"Média",L38<=20%,"Baixa")} -> #NAME? | N38: SIM | O38: =J38 -> 8050 | P38: 0 | Q38: 9100 | R38: 7000 | S38: 0 | T38: 0
B39: Analista de redes/infraestrutura | C39: =B39& " " &D39 -> Analista de redes/infraestrutura Especialista | D39: Especialista | E39: =F39-G39 -> 8800 | F39: 11000 | G39: =F39*$G$9 -> 2200 | H39: =F39+(F39*IF(D39<>"",IF(D39<>"",VLOOKUP(D39,$D$3:$F$9,2,0)),"")) -> 14300 | N39: SIM | O39: =J39 -> 0 | Q39: 0 | R39: 0
B40: Analista de redes/infraestrutura | C40: =B40& " " &D40 -> Analista de redes/infraestrutura Júnior | D40: Júnior | E40: =F40-G40 -> 3200 | F40: 4000 | G40: =F40*$G$9 -> 800 | H40: =F40+(F40*IF(D40<>"",IF(D40<>"",VLOOKUP(D40,$D$3:$F$9,2,0)),"")) -> 5200 | N40: SIM | O40: =J40 -> 0 | Q40: 0 | R40: 0
B41: Analista de redes/infraestrutura | C41: =B41& " " &D41 -> Analista de redes/infraestrutura Pleno | D41: Pleno | E41: =F41-G41 -> 4800 | F41: 6000 | G41: =F41*$G$9 -> 1200 | H41: =F41+(F41*IF(D41<>"",IF(D41<>"",VLOOKUP(D41,$D$3:$F$9,2,0)),"")) -> 7800 | N41: SIM | O41: =J41 -> 0 | Q41: 0 | R41: 0
B42: Analista de redes/infraestrutura | C42: =B42& " " &D42 -> Analista de redes/infraestrutura Sênior | D42: Sênior | E42: =F42-G42 -> 6400 | F42: 8000 | G42: =F42*$G$9 -> 1600 | H42: =F42+(F42*IF(D42<>"",IF(D42<>"",VLOOKUP(D42,$D$3:$F$9,2,0)),"")) -> 10400 | N42: SIM | O42: =J42 -> 0 | Q42: 0 | R42: 0
B43: Analista de Suporte (N1) | C43: =B43& " " &D43 -> Analista de Suporte (N1) Júnior | D43: Júnior | E43: =F43-G43 -> 1840 | F43: 2300 | G43: =F43*$G$9 -> 460 | H43: =F43+(F43*IF(D43<>"",IF(D43<>"",VLOOKUP(D43,$D$3:$F$9,2,0)),"")) -> 2990 | N43: SIM | O43: =J43 -> 0 | Q43: 0 | R43: 0
B44: Analista de Suporte (N1) | C44: =B44& " " &D44 -> Analista de Suporte (N1) Pleno | D44: Pleno | E44: =F44-G44 -> 2720 | F44: 3400 | G44: =F44*$G$9 -> 680 | H44: =F44+(F44*IF(D44<>"",IF(D44<>"",VLOOKUP(D44,$D$3:$F$9,2,0)),"")) -> 4420 | N44: SIM | O44: =J44 -> 0 | Q44: 0 | R44: 0
...

Sheet Rate Card CLT
E2: RESUMO | F2: Base horas mês | G2: 176 | I2: $ salários + encargos | J2: =SUBTOTAL(9,J9:J50012) -> 2773439.8 | L2: FGTS | M2: 0.08 | N2: Nº colab bilable | O2: =COUNTIF(E9:E5012, "Sim") -> 151 | P2: Valor convênio | Q2: 600 | R2: INSS+RAT+TERC | S2: 0.275 | W2: Ajustes do cálculo CLT que precisamos ajustar em todas tabelas
C3: modelo | D3: CLT | F3: % Comissão vend. | G3: 0.03 | I3: $ faturamento | J3: =SUBTOTAL(9,T9:T50012) -> 5284789.6 | L3: FGTS Multa | M3: 0.4 | N3: Nº colab no bilable | O3: =COUNTIF(E9:E5012, "Não") -> 0 | P3: Valor comissão | Q3: =SUM(R9:R54) -> 36444.547 | W3: Ok
C4: Híbrido | D4: Não | F4: % Imposto NF | G4: 0.23 | I4: $ Custos | J4: =SUBTOTAL(9,K9:K5012)+Q3 -> 4025386 | L4: INSS | M4: 0.09 | N4: % Rateio no Bilable | O4: 0 | P4: Soma de horas | Q4: =SUM(D9:D5012) -> 26576 | W4: Incluídos
C5: Perc.Hib. | D5: 0 | G5: 0.85 | I5: $ lucratividade | J5: =J3-J4 -> 1259403.6 | L5: Ticket Rest. Dia | M5: 25 | N5: Total Billable | O5: =L12 -> 113.61332 | P5: hora média | Q5: =J3/Q4 -> 198.85572 | W5: Alterados
F6: Taxa de risco | G6: 0 | I6: % lucro real | J6: =J5/J3 -> 0.23830724 | L6: Tarifa média hr. | M6: =SUM(T9:T5012)/SUM(D9:D5012) -> 198.85572 | N6: Total No Bilable | O6: =SUMIF(E9:E5012,"Não",Q9:Q5012) -> 0 | W6: Remover
B7: CONFIGURAÇÃO EQUIPE | C7: CONFIG RECURSO | F7: C U S T O S C O M C O L A B O R A D O R E S | M7: T A R I F A / F A T U R A M E N T O | V7: C U S T O S C L T | AI7: IMPOSTOS | AJ7: LUCRATIVIDADE
B8: Necessidade cliente | C8: Reg | D8: H.trab | E8: Billable | F8: $ Negociado/salário | G8: $ salário cheio | H8: Vale Refeição/Alimentação | I8: $ Salário real | J8: $ Custo Colab | K8: $ Custo colab + Imp | L8: Custo hora | M8: $ Tarifa negociada | N8: Markup | O8: $ Risco | P8: $ Tarifa | Q8: $ Tar. calculada | R8: $ Comissão | S8: Loc. Equip. | T8: $ Tarifa bilable | U8: Valor hora | V8: FGTS | W8: FGTS multa | X8: Férias | Y8: 1/3 férias | Z8: 13º salário | AA8: INSS+RAT+TERC | AB8: FGTS sobre 13º e Férias | AC8: INSS+RAT+Terc (13º e Fér) | AD8: Aviso Remuner | AE8: FGTS Sobre Aviso | AF8: INSS | AG8: Convênio | AH8: $ Total Encargos | AI8: Imposto Nota | AJ8: $ lucro | AK8: % Lucro | AL8: Marg Contrib
B9: Agilista Especialista | C9: CLT | D9: 176 | E9: Sim | F9: 0 | G9: =IF(F9>0,F9, IF(B9<>"", IF(C9="CLT",VLOOKUP(B9,'Lista Profissionais'!$C$11:$H$348,3,0), VLOOKUP(B9,'Lista Profissionais'!$C$11:$H$348,6,0)), 0)) -> 10800 | H9: =IF(B9<>"", IF(C9="CLT", 22*$M$5 + (G9*'Lista Profissionais'!$G$9),0),0) -> 2710 | I9: =(G9/$G$2)*D9 -> 10800 | J9: =I9+AH9 -> 23273.5 | K9: =J9+S9+AI9 -> 33473.46 | L9: =IF(D9>0,J9/D9,0) -> 132.2358 | N9: 0 | O9: =J9*$G$6 -> 0 | P9: =IF(M9>0,M9, J9*(1+$G$5)) -> 43055.975 | Q9: =(P9+O9) -> 43055.975 | R9: =IF(E9="Sim", Q9*$G$3,0) -> 1291.6792 | S9: 0 | T9: =IF($D$4="Sim",(IF(E9="Não",0,(Q9+(Q9*$O$4)+R9+S9)*$D$5)+Q9), IF(E9="Não",0,Q9+(Q9*$O$4)+R9+S9 )) -> 44347.654 | U9: =IF(D9>0,T9/D9,0) -> 251.97531 | V9: =IF(C9="CLT", I9*$M$2, 0) -> 864 | W9: =IF(C9="CLT", V9*$M$3, 0) -> 345.6 | X9: =IF(C9="CLT", I9/12, 0) -> 900 | Y9: =IF(C9="CLT", X9/3, 0) -> 300 | Z9: =IF(C9="CLT", I9/12, 0) -> 900 | AA9: =IF(C9="CLT", I9*$S$2,0) -> 2970 | AB9: =IF(C9="CLT", SUM(X9:Z9) * $M$2,0) -> 168 | AC9: =IF(C9="CLT", SUM(X9:Z9)*$S$2,0) -> 577.5 | AD9: =IF(C9="CLT", I9/30*3, 0) -> 1080 | AE9: =IF(C9="CLT", AD9*$M$2, 0) -> 86.4 | AF9: =IF(C9="CLT", I9*$M$4, 0) -> 972 | AG9: =IF(B9<>"", IF(C9="CLT", $Q$2, 0),0) -> 600 | AH9: =SUM(V9:AG9)+H9 -> 12473.5 | AI9: =IF(E9="Sim", T9*$G$4, 0) -> 10199.96 | AJ9: =T9-AI9-J9-R9 -> 9582.5145 | AK9: =(IF(AJ9>0,AJ9/T9,0)) -> 0.21607715 | AL9: =(IF(AJ9>0,AJ9/(T9-AI9),0)) -> 0.28061967
B10: Agilista - Junior Júnior | C10: CLT | D10: 176 | E10: Sim | F10: 0 | G10: =IF(F10>0,F10, IF(B10<>"", IF(C10="CLT",VLOOKUP(B10,'Lista Profissionais'!$C$11:$H$348,3,0), VLOOKUP(B10,'Lista Profissionais'!$C$11:$H$348,6,0)), 0)) -> 3920 | H10: =IF(B10<>"", IF(C10="CLT", 22*$M$5 + (G10*'Lista Profissionais'!$G$9),0),0) -> 1334 | I10: =(G10/$G$2)*D10 -> 3920 | J10: =I10+AH10 -> 9180.0111 | K10: =J10+S10+AI10 -> 13203.289 | L10: =IF(D10>0,J10/D10,0) -> 52.159154 | N10: 0 | O10: =J10*$G$6 -> 0 | P10: =IF(M10>0,M10, J10*(1+$G$5)) -> 16983.021 | Q10: =(P10+O10) -> 16983.021 | R10: =IF(E10="Sim", Q10*$G$3,0) -> 509.49062 | S10: 0 | T10: =IF($D$4="Sim",(IF(E10="Não",0,(Q10+(Q10*$O$4)+R10+S10)*$D$5)+Q10), IF(E10="Não",0,Q10+(Q10*$O$4)+R10+S10 )) -> 17492.511 | U10: =IF(D10>0,T10/D10,0) -> 99.389268 | V10: =IF(C10="CLT", I10*$M$2, 0) -> 313.6 | W10: =IF(C10="CLT", V10*$M$3, 0) -> 125.44 | X10: =IF(C10="CLT", I10/12, 0) -> 326.66667 | Y10: =IF(C10="CLT", X10/3, 0) -> 108.88889 | Z10: =IF(C10="CLT", I10/12, 0) -> 326.66667 | AA10: =IF(C10="CLT", I10*$S$2,0) -> 1078 | AB10: =IF(C10="CLT", SUM(X10:Z10) * $M$2,0) -> 60.977778 | AC10: =IF(C10="CLT", SUM(X10:Z10)*$S$2,0) -> 209.61111 | AD10: =IF(C10="CLT", I10/30*3, 0) -> 392 | AE10: =IF(C10="CLT", AD10*$M$2, 0) -> 31.36 | AF10: =IF(C10="CLT", I10*$M$4, 0) -> 352.8 | AG10: =IF(B10<>"", IF(C10="CLT", $Q$2, 0),0) -> 600 | AH10: =SUM(V10:AG10)+H10 -> 5260.0111 | AI10: =IF(E10="Sim", T10*$G$4, 0) -> 4023.2776 | AJ10: =T10-AI10-J10-R10 -> 3779.7319 | AK10: =(IF(AJ10>0,AJ10/T10,0)) -> 0.21607715 | AL10: =(IF(AJ10>0,AJ10/(T10-AI10),0)) -> 0.28061967
B11: Agilista Pleno | C11: CLT | D11: 176 | E11: Sim | F11: 0 | G11: =IF(F11>0,F11, IF(B11<>"", IF(C11="CLT",VLOOKUP(B11,'Lista Profissionais'!$C$11:$H$348,3,0), VLOOKUP(B11,'Lista Profissionais'!$C$11:$H$348,6,0)), 0)) -> 6320 | H11: =IF(B11<>"", IF(C11="CLT", 22*$M$5 + (G11*'Lista Profissionais'!$G$9),0),0) -> 1814 | I11: =(G11/$G$2)*D11 -> 6320 | J11: =I11+AH11 -> 14096.344 | K11: =J11+S11+AI11 -> 20274.279 | L11: =IF(D11>0,J11/D11,0) -> 80.092866 | N11: 0 | O11: =J11*$G$6 -> 0 | P11: =IF(M11>0,M11, J11*(1+$G$5)) -> 26078.237 | Q11: =(P11+O11) -> 26078.237 | R11: =IF(E11="Sim", Q11*$G$3,0) -> 782.34712 | S11: 0 | T11: =IF($D$4="Sim",(IF(E11="Não",0,(Q11+(Q11*$O$4)+R11+S11)*$D$5)+Q11), IF(E11="Não",0,Q11+(Q11*$O$4)+R11+S11 )) -> 26860.584 | U11: =IF(D11>0,T11/D11,0) -> 152.61696 | V11: =IF(C11="CLT", I11*$M$2, 0) -> 505.6 | W11: =IF(C11="CLT", V11*$M$3, 0) -> 202.24 | X11: =IF(C11="CLT", I11/12, 0) -> 526.66667 | Y11: =IF(C11="CLT", X11/3, 0) -> 175.55556 | Z11: =IF(C11="CLT", I11/12, 0) -> 526.66667 | AA11: =IF(C11="CLT", I11*$S$2,0) -> 1738 | AB11: =IF(C11="CLT", SUM(X11:Z11) * $M$2,0) -> 98.311111 | AC11: =IF(C11="CLT", SUM(X11:Z11)*$S$2,0) -> 337.94444 | AD11: =IF(C11="CLT", I11/30*3, 0) -> 632 | AE11: =IF(C11="CLT", AD11*$M$2, 0) -> 50.56 | AF11: =IF(C11="CLT", I11*$M$4, 0) -> 568.8 | AG11: =IF(B11<>"", IF(C11="CLT", $Q$2, 0),0) -> 600 | AH11: =SUM(V11:AG11)+H11 -> 7776.3444 | AI11: =IF(E11="Sim", T11*$G$4, 0) -> 6177.9344 | AJ11: =T11-AI11-J11-R11 -> 5803.9584 | AK11: =(IF(AJ11>0,AJ11/T11,0)) -> 0.21607715 | AL11: =(IF(AJ11>0,AJ11/(T11-AI11),0)) -> 0.28061967
B12: Agilista Sênior | C12: CLT | D12: 176 | E12: Sim | F12: 0 | G12: =IF(F12>0,F12, IF(B12<>"", IF(C12="CLT",VLOOKUP(B12,'Lista Profissionais'!$C$11:$H$348,3,0), VLOOKUP(B12,'Lista Profissionais'!$C$11:$H$348,6,0)), 0)) -> 9200 | H12: =IF(B12<>"", IF(C12="CLT", 22*$M$5 + (G12*'Lista Profissionais'!$G$9),0),0) -> 2390 | I12: =(G12/$G$2)*D12 -> 9200 | J12: =I12+AH12 -> 19995.944 | K12: =J12+S12+AI12 -> 28759.467 | L12: =IF(D12>0,J12/D12,0) -> 113.61332 | N12: 0 | O12: =J12*$G$6 -> 0 | P12: =IF(M12>0,M12, J12*(1+$G$5)) -> 36992.497 | Q12: =(P12+O12) -> 36992.497 | R12: =IF(E12="Sim", Q12*$G$3,0) -> 1109.7749 | S12: 0 | T12: =IF($D$4="Sim",(IF(E12="Não",0,(Q12+(Q12*$O$4)+R12+S12)*$D$5)+Q12), IF(E12="Não",0,Q12+(Q12*$O$4)+R12+S12 )) -> 38102.272 | U12: =IF(D12>0,T12/D12,0) -> 216.49018 | V12: =IF(C12="CLT", I12*$M$2, 0) -> 736 | W12: =IF(C12="CLT", V12*$M$3, 0) -> 294.4 | X12: =IF(C12="CLT", I12/12, 0) -> 766.66667 | Y12: =IF(C12="CLT", X12/3, 0) -> 255.55556 | Z12: =IF(C12="CLT", I12/12, 0) -> 766.66667 | AA12: =IF(C12="CLT", I12*$S$2,0) -> 2530 | AB12: =IF(C12="CLT", SUM(X12:Z12) * $M$2,0) -> 143.11111 | AC12: =IF(C12="CLT", SUM(X12:Z12)*$S$2,0) -> 491.94444 | AD12: =IF(C12="CLT", I12/30*3, 0) -> 920 | AE12: =IF(C12="CLT", AD12*$M$2, 0) -> 73.6 | AF12: =IF(C12="CLT", I12*$M$4, 0) -> 828 | AG12: =IF(B12<>"", IF(C12="CLT", $Q$2, 0),0) -> 600 | AH12: =SUM(V12:AG12)+H12 -> 10795.944 | AI12: =IF(E12="Sim", T12*$G$4, 0) -> 8763.5226 | AJ12: =T12-AI12-J12-R12 -> 8233.0302 | AK12: =(IF(AJ12>0,AJ12/T12,0)) -> 0.21607715 | AL12: =(IF(AJ12>0,AJ12/(T12-AI12),0)) -> 0.28061967
B13: Analista de Dados/ BI Especialista | C13: CLT | D13: 176 | E13: Sim | F13: 0 | G13: =IF(F13>0,F13, IF(B13<>"", IF(C13="CLT",VLOOKUP(B13,'Lista Profissionais'!$C$11:$H$348,3,0), VLOOKUP(B13,'Lista Profissionais'!$C$11:$H$348,6,0)), 0)) -> 8800 | H13: =IF(B13<>"", IF(C13="CLT", 22*$M$5 + (G13*'Lista Profissionais'!$G$9),0),0) -> 2310 | I13: =(G13/$G$2)*D13 -> 8800 | J13: =I13+AH13 -> 19176.556 | K13: =J13+S13+AI13 -> 27580.969 | L13: =IF(D13>0,J13/D13,0) -> 108.9577 | N13: 0 | O13: =J13*$G$6 -> 0 | P13: =IF(M13>0,M13, J13*(1+$G$5)) -> 35476.628 | Q13: =(P13+O13) -> 35476.628 | R13: =IF(E13="Sim", Q13*$G$3,0) -> 1064.2988 | S13: 0 | T13: =IF($D$4="Sim",(IF(E13="Não",0,(Q13+(Q13*$O$4)+R13+S13)*$D$5)+Q13), IF(E13="Não",0,Q13+(Q13*$O$4)+R13+S13 )) -> 36540.927 | U13: =IF(D13>0,T13/D13,0) -> 207.6189 | V13: =IF(C13="CLT", I13*$M$2, 0) -> 704 | W13: =IF(C13="CLT", V13*$M$3, 0) -> 281.6 | X13: =IF(C13="CLT", I13/12, 0) -> 733.33333 | Y13: =IF(C13="CLT", X13/3, 0) -> 244.44444 | Z13: =IF(C13="CLT", I13/12, 0) -> 733.33333 | AA13: =IF(C13="CLT", I13*$S$2,0) -> 2420 | AB13: =IF(C13="CLT", SUM(X13:Z13) * $M$2,0) -> 136.88889 | AC13: =IF(C13="CLT", SUM(X13:Z13)*$S$2,0) -> 470.55556 | AD13: =IF(C13="CLT", I13/30*3, 0) -> 880 | AE13: =IF(C13="CLT", AD13*$M$2, 0) -> 70.4 | AF13: =IF(C13="CLT", I13*$M$4, 0) -> 792 | AG13: =IF(B13<>"", IF(C13="CLT", $Q$2, 0),0) -> 600 | AH13: =SUM(V13:AG13)+H13 -> 10376.556 | AI13: =IF(E13="Sim", T13*$G$4, 0) -> 8404.4131 | AJ13: =T13-AI13-J13-R13 -> 7895.6591 | AK13: =(IF(AJ13>0,AJ13/T13,0)) -> 0.21607715 | AL13: =(IF(AJ13>0,AJ13/(T13-AI13),0)) -> 0.28061967
B14: Analista de Dados/ BI Júnior | C14: CLT | D14: 176 | E14: Sim | F14: 0 | G14: =IF(F14>0,F14, IF(B14<>"", IF(C14="CLT",VLOOKUP(B14,'Lista Profissionais'!$C$11:$H$348,3,0), VLOOKUP(B14,'Lista Profissionais'!$C$11:$H$348,6,0)), 0)) -> 3360 | H14: =IF(B14<>"", IF(C14="CLT", 22*$M$5 + (G14*'Lista Profissionais'!$G$9),0),0) -> 1222 | I14: =(G14/$G$2)*D14 -> 3360 | J14: =I14+AH14 -> 8032.8667 | K14: =J14+S14+AI14 -> 11553.391 | L14: =IF(D14>0,J14/D14,0) -> 45.641288 | N14: 0 | O14: =J14*$G$6 -> 0 | P14: =IF(M14>0,M14, J14*(1+$G$5)) -> 14860.803 | Q14: =(P14+O14) -> 14860.803 | R14: =IF(E14="Sim", Q14*$G$3,0) -> 445.8241 | S14: 0 | T14: =IF($D$4="Sim",(IF(E14="Não",0,(Q14+(Q14*$O$4)+R14+S14)*$D$5)+Q14), IF(E14="Não",0,Q14+(Q14*$O$4)+R14+S14 )) -> 15306.627 | U14: =IF(D14>0,T14/D14,0) -> 86.969474 | V14: =IF(C14="CLT", I14*$M$2, 0) -> 268.8 | W14: =IF(C14="CLT", V14*$M$3, 0) -> 107.52 | X14: =IF(C14="CLT", I14/12, 0) -> 280 | Y14: =IF(C14="CLT", X14/3, 0) -> 93.333333 | Z14: =IF(C14="CLT", I14/12, 0) -> 280 | AA14: =IF(C14="CLT", I14*$S$2,0) -> 924 | AB14: =IF(C14="CLT", SUM(X14:Z14) * $M$2,0) -> 52.266667 | AC14: =IF(C14="CLT", SUM(X14:Z14)*$S$2,0) -> 179.66667 | AD14: =IF(C14="CLT", I14/30*3, 0) -> 336 | AE14: =IF(C14="CLT", AD14*$M$2, 0) -> 26.88 | AF14: =IF(C14="CLT", I14*$M$4, 0) -> 302.4 | AG14: =IF(B14<>"", IF(C14="CLT", $Q$2, 0),0) -> 600 | AH14: =SUM(V14:AG14)+H14 -> 4672.8667 | AI14: =IF(E14="Sim", T14*$G$4, 0) -> 3520.5243 | AJ14: =T14-AI14-J14-R14 -> 3307.4124 | AK14: =(IF(AJ14>0,AJ14/T14,0)) -> 0.21607715 | AL14: =(IF(AJ14>0,AJ14/(T14-AI14),0)) -> 0.28061967
B15: Analista de Dados/ BI Pleno | C15: CLT | D15: 176 | E15: Sim | F15: 0 | G15: =IF(F15>0,F15, IF(B15<>"", IF(C15="CLT",VLOOKUP(B15,'Lista Profissionais'!$C$11:$H$348,3,0), VLOOKUP(B15,'Lista Profissionais'!$C$11:$H$348,6,0)), 0)) -> 6000 | H15: =IF(B15<>"", IF(C15="CLT", 22*$M$5 + (G15*'Lista Profissionais'!$G$9),0),0) -> 1750 | I15: =(G15/$G$2)*D15 -> 6000 | J15: =I15+AH15 -> 13440.833 | K15: =J15+S15+AI15 -> 19331.48 | L15: =IF(D15>0,J15/D15,0) -> 76.368371 | N15: 0 | O15: =J15*$G$6 -> 0 | P15: =IF(M15>0,M15, J15*(1+$G$5)) -> 24865.542 | Q15: =(P15+O15) -> 24865.542 | R15: =IF(E15="Sim", Q15*$G$3,0) -> 745.96625 | S15: 0 | T15: =IF($D$4="Sim",(IF(E15="Não",0,(Q15+(Q15*$O$4)+R15+S15)*$D$5)+Q15), IF(E15="Não",0,Q15+(Q15*$O$4)+R15+S15 )) -> 25611.508 | U15: =IF(D15>0,T15/D15,0) -> 145.51993 | V15: =IF(C15="CLT", I15*$M$2, 0) -> 480 | W15: =IF(C15="CLT", V15*$M$3, 0) -> 192 | X15: =IF(C15="CLT", I15/12, 0) -> 500 | Y15: =IF(C15="CLT", X15/3, 0) -> 166.66667 | Z15: =IF(C15="CLT", I15/12, 0) -> 500 | AA15: =IF(C15="CLT", I15*$S$2,0) -> 1650 | AB15: =IF(C15="CLT", SUM(X15:Z15) * $M$2,0) -> 93.333333 | AC15: =IF(C15="CLT", SUM(X15:Z15)*$S$2,0) -> 320.83333 | AD15: =IF(C15="CLT", I15/30*3, 0) -> 600 | AE15: =IF(C15="CLT", AD15*$M$2, 0) -> 48 | AF15: =IF(C15="CLT", I15*$M$4, 0) -> 540 | AG15: =IF(B15<>"", IF(C15="CLT", $Q$2, 0),0) -> 600 | AH15: =SUM(V15:AG15)+H15 -> 7440.8333 | AI15: =IF(E15="Sim", T15*$G$4, 0) -> 5890.6468 | AJ15: =T15-AI15-J15-R15 -> 5534.0615 | AK15: =(IF(AJ15>0,AJ15/T15,0)) -> 0.21607715 | AL15: =(IF(AJ15>0,AJ15/(T15-AI15),0)) -> 0.28061967
B16: Analista de Dados/ BI Sênior | C16: CLT | D16: 176 | E16: Sim | F16: 0 | G16: =IF(F16>0,F16, IF(B16<>"", IF(C16="CLT",VLOOKUP(B16,'Lista Profissionais'!$C$11:$H$348,3,0), VLOOKUP(B16,'Lista Profissionais'!$C$11:$H$348,6,0)), 0)) -> 7600 | H16: =IF(B16<>"", IF(C16="CLT", 22*$M$5 + (G16*'Lista Profissionais'!$G$9),0),0) -> 2070 | I16: =(G16/$G$2)*D16 -> 7600 | J16: =I16+AH16 -> 16718.389 | K16: =J16+S16+AI16 -> 24045.474 | L16: =IF(D16>0,J16/D16,0) -> 94.990846 | N16: 0 | O16: =J16*$G$6 -> 0 | P16: =IF(M16>0,M16, J16*(1+$G$5)) -> 30929.019 | Q16: =(P16+O16) -> 30929.019 | R16: =IF(E16="Sim", Q16*$G$3,0) -> 927.87058 | S16: 0 | T16: =IF($D$4="Sim",(IF(E16="Não",0,(Q16+(Q16*$O$4)+R16+S16)*$D$5)+Q16), IF(E16="Não",0,Q16+(Q16*$O$4)+R16+S16 )) -> 31856.89 | U16: =IF(D16>0,T16/D16,0) -> 181.00506 | V16: =IF(C16="CLT", I16*$M$2, 0) -> 608 | W16: =IF(C16="CLT", V16*$M$3, 0) -> 243.2 | X16: =IF(C16="CLT", I16/12, 0) -> 633.33333 | Y16: =IF(C16="CLT", X16/3, 0) -> 211.11111 | Z16: =IF(C16="CLT", I16/12, 0) -> 633.33333 | AA16: =IF(C16="CLT", I16*$S$2,0) -> 2090 | AB16: =IF(C16="CLT", SUM(X16:Z16) * $M$2,0) -> 118.22222 | AC16: =IF(C16="CLT", SUM(X16:Z16)*$S$2,0) -> 406.38889 | AD16: =IF(C16="CLT", I16/30*3, 0) -> 760 | AE16: =IF(C16="CLT", AD16*$M$2, 0) -> 60.8 | AF16: =IF(C16="CLT", I16*$M$4, 0) -> 684 | AG16: =IF(B16<>"", IF(C16="CLT", $Q$2, 0),0) -> 600 | AH16: =SUM(V16:AG16)+H16 -> 9118.3889 | AI16: =IF(E16="Sim", T16*$G$4, 0) -> 7327.0847 | AJ16: =T16-AI16-J16-R16 -> 6883.5458 | AK16: =(IF(AJ16>0,AJ16/T16,0)) -> 0.21607715 | AL16: =(IF(AJ16>0,AJ16/(T16-AI16),0)) -> 0.28061967
B17: Analista de Inteligência Artificial Especialista | C17: CLT | D17: 176 | E17: Sim | F17: 0 | G17: =IF(F17>0,F17, IF(B17<>"", IF(C17="CLT",VLOOKUP(B17,'Lista Profissionais'!$C$11:$H$348,3,0), VLOOKUP(B17,'Lista Profissionais'!$C$11:$H$348,6,0)), 0)) -> 10800 | H17: =IF(B17<>"", IF(C17="CLT", 22*$M$5 + (G17*'Lista Profissionais'!$G$9),0),0) -> 2710 | I17: =(G17/$G$2)*D17 -> 10800 | J17: =I17+AH17 -> 23273.5 | K17: =J17+S17+AI17 -> 33473.46 | L17: =IF(D17>0,J17/D17,0) -> 132.2358 | N17: 0 | O17: =J17*$G$6 -> 0 | P17: =IF(M17>0,M17, J17*(1+$G$5)) -> 43055.975 | Q17: =(P17+O17) -> 43055.975 | R17: =IF(E17="Sim", Q17*$G$3,0) -> 1291.6792 | S17: 0 | T17: =IF($D$4="Sim",(IF(E17="Não",0,(Q17+(Q17*$O$4)+R17+S17)*$D$5)+Q17), IF(E17="Não",0,Q17+(Q17*$O$4)+R17+S17 )) -> 44347.654 | U17: =IF(D17>0,T17/D17,0) -> 251.97531 | V17: =IF(C17="CLT", I17*$M$2, 0) -> 864 | W17: =IF(C17="CLT", V17*$M$3, 0) -> 345.6 | X17: =IF(C17="CLT", I17/12, 0) -> 900 | Y17: =IF(C17="CLT", X17/3, 0) -> 300 | Z17: =IF(C17="CLT", I17/12, 0) -> 900 | AA17: =IF(C17="CLT", I17*$S$2,0) -> 2970 | AB17: =IF(C17="CLT", SUM(X17:Z17) * $M$2,0) -> 168 | AC17: =IF(C17="CLT", SUM(X17:Z17)*$S$2,0) -> 577.5 | AD17: =IF(C17="CLT", I17/30*3, 0) -> 1080 | AE17: =IF(C17="CLT", AD17*$M$2, 0) -> 86.4 | AF17: =IF(C17="CLT", I17*$M$4, 0) -> 972 | AG17: =IF(B17<>"", IF(C17="CLT", $Q$2, 0),0) -> 600 | AH17: =SUM(V17:AG17)+H17 -> 12473.5 | AI17: =IF(E17="Sim", T17*$G$4, 0) -> 10199.96 | AJ17: =T17-AI17-J17-R17 -> 9582.5145 | AK17: =(IF(AJ17>0,AJ17/T17,0)) -> 0.21607715 | AL17: =(IF(AJ17>0,AJ17/(T17-AI17),0)) -> 0.28061967
